Workbook

Sheet Bảng thông tin
A1: STT | B1: MÃ NV | C1: HỌ VÀ TÊN | D1: LOẠI HĐ | E1: CHỨC VỤ | F1: PHÒNG BAN | G1: Bậc lương | H1: LƯƠNG ĐÓNG BHXH | I1: LƯƠNG CƠ BẢN | J1: PHỤ CẤP TRÁCH NHIỆM | K1: TIỀN ĂN | L1: XĂNG XE | M1: ĐIỆN THOẠI | N1: TRANG PHỤC | O1: TỔNG LƯƠNG THEO HĐLĐ | P1: PHÚC LỢI (Thưởng Lễ, Tết, T13, Sinh nhật) | R1: TẠM ỨNG | S1: TÌNH TRẠNG
P2: Sinh nhật | Q2: Thưởng
B3: 1 | C3: 2 | D3: 3 | E3: 4 | F3: 5 | G3: 6 | H3: 7 | I3: 8 | J3: 9 | K3: 10 | L3: 11 | M3: 12 | N3: 13 | O3: 14 | P3: 15 | Q3: 16 | R3: 17 | S3: 18
A4: 1 | B4: QL001 | C4: Phạm Đăng Anh Thư | D4: HĐLĐ | E4: Tổng Giám Đốc | F4: Ban giám đốc | H4: =+IF($D4="HĐTV","",I4+J4) -> 18000000 | I4: 15000000 | J4: 3000000 | K4: 2600000 | L4: 0 | M4: 4000000 | N4: 400000 | O4: =SUM(I4:N4) -> 25000000 | R4: 0 | S4: 0
A5: 2 | B5: QL002 | C5: Nguyễn Diệp Anh Tuấn | D5: HĐLĐ | E5: Giám Đốc | F5: Ban giám đốc | H5: =+IF($D5="HĐTV","",I5+J5) -> 14000000 | I5: 12000000 | J5: 2000000 | K5: 2000000 | L5: 1000000 | M5: 2600000 | N5: 400000 | O5: =SUM(I5:N5) -> 20000000
A6: 3 | B6: NV001 | C6: Nguyễn Thị Châu Loan | D6: HĐLĐ | E6: Trưởng phòng | F6: Logistic | H6: =+IF($D6="HĐTV","",I6+J6) -> 8500000 | I6: 7500000 | J6: 1000000 | K6: 1800000 | L6: 500000 | M6: 400000 | N6: 400000 | O6: =SUM(I6:N6) -> 11600000
A7: 4 | B7: NV003 | C7: Nguyễn Diệu Quý Chi | D7: HĐLĐ | E7: Trưởng phòng | F7: Kinh doanh | H7: =+IF($D7="HĐTV","",I7+J7) -> 8500000 | I7: 7500000 | J7: 1000000 | K7: 1800000 | L7: 500000 | M7: 400000 | N7: 400000 | O7: =SUM(I7:N7) -> 11600000
A8: 5 | B8: NV004 | C8: Phạm Đăng Anh Thảo | D8: HĐLĐ | E8: Phó phòng | F8: Kinh doanh | H8: =+IF($D8="HĐTV","",I8+J8) -> 8000000 | I8: 7000000 | J8: 1000000 | K8: 1300000 | L8: 500000 | M8: 400000 | N8: 400000 | O8: =SUM(I8:N8) -> 10600000
A9: 6 | B9: NV005 | C9: Nguyễn Văn Thái | D9: HĐLĐ | E9: Phó phòng | F9: Logistic | H9: =+IF($D9="HĐTV","",I9+J9) -> 8000000 | I9: 7000000 | J9: 1000000 | K9: 1300000 | L9: 500000 | M9: 400000 | N9: 400000 | O9: =SUM(I9:N9) -> 10600000
A10: 7 | B10: NV006 | C10: Dương Nguyễn Anh Khoa | D10: HĐLĐ | E10: Trưởng phòng | F10: Sản xuất | H10: =+IF($D10="HĐTV","",I10+J10) -> 8500000 | I10: 7500000 | J10: 1000000 | K10: 1800000 | L10: 500000 | M10: 400000 | N10: 400000 | O10: =SUM(I10:N10) -> 11600000
A11: 8 | B11: NV007 | C11: Mai Hà Xuân Phúc | D11: HĐLĐ | E11: Phó phòng | F11: Sản xuất | H11: =+IF($D11="HĐTV","",I11+J11) -> 8000000 | I11: 7000000 | J11: 1000000 | K11: 1300000 | L11: 500000 | M11: 400000 | N11: 400000 | O11: =SUM(I11:N11) -> 10600000
A12: 9 | B12: NV009 | C12: Trần Thị Thanh Dung | D12: HĐLĐ | E12: Kế toán | F12: Kế toán | H12: =+IF($D12="HĐTV","",I12+J12) -> 8500000 | I12: 7500000 | J12: 1000000 | K12: 1800000 | L12: 500000 | M12: 300000 | N12: 400000 | O12: =SUM(I12:N12) -> 11500000 | T12: Báo giảm BH tháng 7
A13: 10 | B13: NV010 | C13: Lê Hữu Thọ | D13: HĐLĐ | E13: Thủ kho trưởng | F13: Logistic | H13: =+IF($D13="HĐTV","",I13+J13) -> 8000000 | I13: 7000000 | J13: 1000000 | K13: 1300000 | L13: 500000 | M13: 400000 | N13: 400000 | O13: =SUM(I13:N13) -> 10600000
A14: 11 | B14: NV011 | C14: Nguyễn Thành Long | D14: HĐLĐ | E14: Nhân viên | F14: Kinh doanh | H14: =+IF($D14="HĐTV","",I14+J14) -> 7000000 | I14: 6500000 | J14: 500000 | K14: 1000000 | L14: 500000 | M14: 300000 | N14: 400000 | O14: =SUM(I14:N14) -> 9200000
A15: 12 | B15: NV012 | C15: Nguyễn Thị Đài Trang | D15: HĐLĐ | E15: Nhân viên | F15: Kinh doanh | H15: =+IF($D15="HĐTV","",I15+J15) -> 7000000 | I15: 6500000 | J15: 500000 | K15: 1000000 | L15: 500000 | M15: 300000 | N15: 400000 | O15: =SUM(I15:N15) -> 9200000
A16: 13 | B16: NV015 | C16: Võ Thị Hoà | D16: HĐLĐ | E16: Tổ trưởng tổ 1 | F16: Sản xuất | H16: =+IF($D16="HĐTV","",I16+J16) -> 8500000 | I16: 7500000 | J16: 1000000 | K16: 1800000 | L16: 500000 | M16: 300000 | N16: 400000 | O16: =SUM(I16:N16) -> 11500000
A17: 14 | B17: NV016 | C17: Cao Ngân Giang | D17: HĐLĐ | E17: Nhân viên | F17: Sản xuất | H17: =+IF($D17="HĐTV","",I17+J17) -> 7000000 | I17: 6500000 | J17: 500000 | K17: 1000000 | L17: 500000 | M17: 300000 | N17: 400000 | O17: =SUM(I17:N17) -> 9200000
A18: 15 | B18: NV017 | C18: Lê Thị Hà | D18: HĐLĐ | E18: Nhân viên | F18: Sản xuất | H18: =+IF($D18="HĐTV","",I18+J18) -> 7000000 | I18: 6500000 | J18: 500000 | K18: 1000000 | L18: 500000 | M18: 300000 | N18: 400000 | O18: =SUM(I18:N18) -> 9200000
A19: 16 | B19: NV018 | C19: Nguyễn A Khương | D19: HĐLĐ | E19: Nhân viên | F19: Sản xuất | H19: =+IF($D19="HĐTV","",I19+J19) -> 7000000 | I19: 6500000 | J19: 500000 | K19: 1000000 | L19: 500000 | M19: 300000 | N19: 400000 | O19: =SUM(I19:N19) -> 9200000
A20: 17 | B20: NV019 | C20: Nguyễn Thị Minh Thoa | D20: HĐLĐ | E20: Nhân viên | F20: Sản xuất | H20: =+IF($D20="HĐTV","",I20+J20) -> 7000000 | I20: 6500000 | J20: 500000 | K20: 1000000 | L20: 500000 | M20: 300000 | N20: 400000 | O20: =SUM(I20:N20) -> 9200000
A21: 18 | B21: NV020 | C21: Dương Nhựt Thành | D21: HĐLĐ | E21: Nhân viên | F21: Logistic | H21: =+IF($D21="HĐTV","",I21+J21) -> 7000000 | I21: 6500000 | J21: 500000 | K21: 1000000 | L21: 1000000 | M21: 500000 | N21: 400000 | O21: =SUM(I21:N21) -> 9900000
A22: 19 | B22: NV021 | C22: Võ Thị Hoài | D22: HĐLĐ | E22: Tổ trưởng tổ 2 | F22: Sản xuất | H22: =+IF($D22="HĐTV","",I22+J22) -> 8500000 | I22: 7500000 | J22: 1000000 | K22: 1800000 | L22: 500000 | M22: 300000 | N22: 400000 | O22: =SUM(I22:N22) -> 11500000
A23: 20 | B23: NV022 | C23: Du Kim Hân | D23: HĐLĐ | E23: Nhân viên | F23: Sản xuất | H23: =+IF($D23="HĐTV","",I23+J23) -> 7000000 | I23: 6500000 | J23: 500000 | K23: 1000000 | L23: 500000 | M23: 300000 | N23: 400000 | O23: =SUM(I23:N23) -> 9200000
A24: 21 | B24: NV023 | C24: Đặng Thu Sương | D24: HĐLĐ | E24: Nhân viên | F24: Sản xuất | H24: =+IF($D24="HĐTV","",I24+J24) -> 7000000 | I24: 6500000 | J24: 500000 | K24: 1000000 | L24: 500000 | M24: 300000 | N24: 400000 | O24: =SUM(I24:N24) -> 9200000
A25: 22 | B25: NV024 | C25: Trần Tuấn Kiệt | D25: HĐLĐ | E25: Trưởng phòng | F25: Sáng tạo | H25: =+IF($D25="HĐTV","",I25+J25) -> 8500000 | I25: 7500000 | J25: 1000000 | K25: 1800000 | L25: 500000 | M25: 400000 | N25: 400000 | O25: =SUM(I25:N25) -> 11600000 | P25: 500000
A26: 23 | B26: NV025 | C26: Ngô Hồng Thắm | D26: HĐLĐ | E26: Nhân viên | F26: Sản xuất | H26: =+IF($D26="HĐTV","",I26+J26) -> 7000000 | I26: 6500000 | J26: 500000 | K26: 1000000 | L26: 500000 | M26: 300000 | N26: 400000 | O26: =SUM(I26:N26) -> 9200000
A27: 24 | B27: NV026 | C27: Trần Thị Tú Anh | D27: HĐLĐ | E27: Nhân viên | F27: Sản xuất | H27: =+IF($D27="HĐTV","",I27+J27) -> 7000000 | I27: 6500000 | J27: 500000 | K27: 1000000 | L27: 500000 | M27: 300000 | N27: 400000 | O27: =SUM(I27:N27) -> 9200000
A28: 25 | B28: NV027 | C28: Lê Thị Hiếu | D28: HĐLĐ | E28: Nhân viên | F28: Kinh doanh | H28: =+IF($D28="HĐTV","",I28+J28) -> 7000000 | I28: 6500000 | J28: 500000 | K28: 1000000 | L28: 500000 | M28: 300000 | N28: 400000 | O28: =SUM(I28:N28) -> 9200000
A29: 26 | B29: NV030 | C29: Vương Thị Ngọc Như | D29: HĐLĐ | E29: Nhân viên tư vấn | F29: Kinh doanh | H29: =+IF($D29="HĐTV","",I29+J29) -> 6000000 | I29: 5500000 | J29: 500000 | K29: 1000000 | M29: 200000 | N29: 300000 | O29: =SUM(I29:N29) -> 7500000
A30: 27 | B30: NV031 | C30: Tiết Trinh Nguyên | D30: HĐLĐ | E30: Nhân viên | F30: Logistic | H30: =+IF($D30="HĐTV","",I30+J30) -> 7000000 | I30: 6500000 | J30: 500000 | K30: 1000000 | L30: 500000 | M30: 300000 | N30: 400000 | O30: =SUM(I30:N30) -> 9200000
A31: 28 | B31: NV032 | C31: Trần Ái Nhi | D31: HĐLĐ | E31: Nhân viên | F31: Sản xuất | H31: =+IF($D31="HĐTV","",I31+J31) -> 7000000 | I31: 6500000 | J31: 500000 | K31: 1000000 | L31: 500000 | M31: 300000 | N31: 400000 | O31: =SUM(I31:N31) -> 9200000
A32: 29 | B32: NV033 | C32: Vũ Thị Loan | D32: HĐLĐ | E32: Nhân viên | F32: Sản xuất | H32: =+IF($D32="HĐTV","",I32+J32) -> 7000000 | I32: 6500000 | J32: 500000 | K32: 1000000 | L32: 500000 | M32: 300000 | N32: 400000 | O32: =SUM(I32:N32) -> 9200000 | P32: 300000
A33: 30 | B33: NV034 | C33: Lê Các Anh | D33: HĐLĐ | E33: Nhân viên | F33: Sản xuất | H33: =+IF($D33="HĐTV","",I33+J33) -> 6500000 | I33: 6000000 | J33: 500000 | K33: 1000000 | L33: 500000 | M33: 300000 | N33: 400000 | O33: =SUM(I33:N33) -> 8700000
A34: 31 | B34: NV035 | C34: Nguyễn Ngọc Bích | D34: HĐLĐ | E34: Nhân viên | F34: Sản xuất | H34: =+IF($D34="HĐTV","",I34+J34) -> 6500000 | I34: 6000000 | J34: 500000 | K34: 1000000 | L34: 500000 | M34: 300000 | N34: 400000 | O34: =SUM(I34:N34) -> 8700000
A35: 32 | B35: NV036 | C35: Nguyễn Hoàng Ngọc Châu | D35: HĐLĐ | E35: Nhân viên | F35: Logistic | H35: =+IF($D35="HĐTV","",I35+J35) -> 7500000 | I35: 6500000 | J35: 1000000 | K35: 1000000 | L35: 500000 | M35: 400000 | N35: 400000 | O35: =SUM(I35:N35) -> 9800000 | S35: Báo tăng BHXH tháng 06
A36: 33 | B36: NV037 | C36: Vũ Thị Mai Thủy | D36: HĐLĐ | E36: Kế toán trưởng | F36: Kế toán | H36: =+IF($D36="HĐTV","",I36+J36) -> 10000000 | I36: 8500000 | J36: 1500000 | K36: 1800000 | L36: 500000 | M36: 500000 | N36: 400000 | O36: =SUM(I36:N36) -> 13200000 | S36: Báo tăng BHXH tháng 06
A37: 34 | B37: NV038 | C37: Phạm Thị Kim Trang | D37: HĐLĐ | E37: Nhân viên | F37: Kinh doanh | H37: =+IF($D37="HĐTV","",I37+J37) -> 7000000 | I37: 6500000 | J37: 500000 | K37: 1000000 | L37: 500000 | M37: 400000 | N37: 400000 | O37: =SUM(I37:N37) -> 9300000 | T37: Hết tháng 7 nghỉ việc
A38: 35 | B38: NV039 | C38: Nguyễn Ngọc Hân | D38: HĐLĐ | E38: Nhân viên tư vấn | F38: Kinh doanh | H38: =+IF($D38="HĐTV","",I38+J38) -> 6000000 | I38: 5500000 | J38: 500000 | K38: 1000000 | L38: 500000 | M38: 400000 | N38: 400000 | O38: =SUM(I38:N38) -> 8300000
A39: 36 | B39: NV040 | C39: Trần Thị Ngọc Hân | D39: HĐLĐ | E39: Nhân viên | F39: Sản xuất | H39: =+IF($D39="HĐTV","",I39+J39) -> 6500000 | I39: 6000000 | J39: 500000 | K39: 1000000 | L39: 500000 | M39: 400000 | N39: 400000 | O39: =SUM(I39:N39) -> 8800000
A40: 37 | B40: NV041 | C40: Võ Thị Xuân Dung | D40: HĐLĐ | E40: Nhân viên | F40: Sản xuất | H40: =+IF($D40="HĐTV","",I40+J40) -> 7000000 | I40: 6500000 | J40: 500000 | K40: 1000000 | L40: 500000 | M40: 400000 | N40: 400000 | O40: =SUM(I40:N40) -> 9300000
...

Sheet Bảng tổng hợp
A1: STT | B1: Mã NV | C1: Họ và tên | D1: Loại HĐ | E1: Chức vụ | F1: Phòng ban | G1: Lương đóng BHXH | H1: Tiền Lương, phụ cấp lương Thỏa thuận trên HĐLĐ | J1: Các khoản hỗ trợ | N1: Tổng lương theo HĐLĐ | O1: Ngày công làm việc thực tế | P1: Số ngày nghỉ hưởng nguyên lương | R1: Số giờ tăng ca thường (150%) | T1: Số giờ ngày nghỉ (200%) | V1: Tiền lương theo ngày công làm việc thực tế | X1: Tiền hỗ trợ theo ngày công thực tế | AB1: Tiền thưởng (thưởng hiệu suất, KPI, T13,phúc lợi) | AC1: Tổng tiền lương thực tế | AD1: Các khoản miễn thuế | AH1: Tổng Thu Nhập Miễn Thuế | AI1: Các khoản Công ty phải đóng | AO1: Các khoản NLĐ phải đóng | AT1: Các khoản Giảm trừ (Bản thân, người phụ thuộc) | AX1: Thu nhập chịu thuế | AY1: Thu nhập tính thuế | AZ1: Thuế TNCN NLĐ phải nộp | BA1: Tạm ứng | BB1: Tổng lương thực lĩnh
B2: 1 | C2: 2 | D2: 3 | E2: 4 | F2: 5 | H2: Lương cơ bản | I2: Phụ Cấp Trách Nhiệm | J2: Tiền ăn | K2: Xăng xe | L2: Điện thoại | M2: Trang phục | P2: Số ngày nghỉ | Q2: Số tiền | R2: Số giờ tăng ca | S2: Số tiền | T2: Số giờ tăng ca | U2: Số tiền | V2: Lương cơ bản | W2: Phụ Cấp Trách Nhiệm | X2: Tiền ăn | Y2: Xăng xe | Z2: Điện thoại | AA2: Trang phục | AD2: Tiền Ăn | AE2: Điện thoại | AF2: Trang phục | AG2: Tiền lương tăng ca | AI2: BHXH (HT(14%) ÔĐ-TS(3%) | AJ2: BHYT (3%) | AK2: BHTN (1%) | AL2: TNLĐBNN (0,5%) | AM2: Tổng cộng | AN2: KPCĐ (2%) | AO2: BHXH (8%) | AP2: BHYT (1,5%) | AQ2: BHTN (1%) | AR2: Tổng cộng | AS2: Phí công đoàn (0.5%) | AT2: GT Bản thân | AU2: Số người phụ thuộc | AV2: Số tiền GTNPT | AW2: Tổng giảm trừ
A3: 1 | B3: 1 | C3: 2 | D3: 3 | E3: 4 | F3: 5 | G3: 6 | H3: 7 | I3: 8 | J3: 9 | K3: 10 | L3: 11 | M3: 12 | N3: 13 | O3: 14 | P3: 15 | Q3: 16 | R3: 17 | S3: 18 | T3: 17 | U3: 18 | V3: 19 | W3: 20 | X3: 21 | Y3: 22 | Z3: 23 | AA3: 24 | AB3: 25 | AC3: 26 | AD3: 27 | AE3: 28 | AF3: 29 | AG3: 30 | AH3: 31 | AJ3: 33 | AK3: 34 | AL3: 35 | AM3: 36 | AN3: 37 | AO3: 38 | AP3: 39 | AQ3: 40 | AR3: 41 | AS3: 42 | AT3: 43 | AU3: 44 | AV3: 45 | AW3: 46 | AX3: 47 | AY3: 48 | AZ3: 49 | BA3: 50 | BB3: 51
A4: 1 | B4: QL001 | C4: =+VLOOKUP($B4,'Bảng thông tin'!$B$4:$R$1002,2,0) -> Phạm Đăng Anh Thư | D4: =+VLOOKUP($B4,'Bảng thông tin'!$B$4:$R$1002,3,0) -> HĐLĐ | E4: =+VLOOKUP($B4,'Bảng thông tin'!$B$4:$R$1002,4,0) -> Tổng Giám Đốc | F4: =+VLOOKUP($B4,'Bảng thông tin'!$B$4:$R$1002,5,0) -> Ban giám đốc | G4: =+VLOOKUP($B4,'Bảng thông tin'!$B$4:$R$1002,7,0) -> 18000000 | H4: =+VLOOKUP($B4,'Bảng thông tin'!$B$4:$R$1002,8,0) -> 15000000 | I4: =+VLOOKUP($B4,'Bảng thông tin'!$B$4:$R$1002,9,0) -> 3000000 | J4: =+VLOOKUP($B4,'Bảng thông tin'!$B$4:$R$1002,10,0) -> 2600000 | K4: =+VLOOKUP($B4,'Bảng thông tin'!$B$4:$R$1002,11,0) -> 0 | L4: =+VLOOKUP($B4,'Bảng thông tin'!$B$4:$R$1002,12,0) -> 4000000 | M4: =+VLOOKUP($B4,'Bảng thông tin'!$B$4:$R$1002,13,0) -> 400000 | N4: =+VLOOKUP($B4,'Bảng thông tin'!$B$4:$R$1002,14,0) -> 25000000 | O4: =VLOOKUP($B4,BCC!$B$11:$AN$1032,35,0) -> 26 | P4: =VLOOKUP($B4,BCC!$B$11:$AN$1032,38,0)+VLOOKUP($B4,BCC!$B$11:$AN$1032,39,0) -> 0 | Q4: =+((H4+I4)/26)*P4 -> 0 | R4: =VLOOKUP($B4,BCC!$B$11:$AN$1032,36,0) -> 8 | S4: =ROUND(((H4+I4)/26)/8*R4*1.5,0) -> 1038462 | T4: =VLOOKUP($B4,BCC!$B$11:$AN$1032,37,0) -> 0 | U4: =ROUND(((H4+I4)/26)/8*T4*2,0) -> 0 | V4: =IF($D4="HĐTV",(H4/26)*$O4*0.85,(H4/26)*$O4) -> 15000000 | W4: =IF($D4="HĐTV",(I4/26)*$O4*0.85,($I4/26)*$O4) -> 3000000 | X4: =(J4/26)*$O4 -> 2600000 | Y4: =(K4/26)*$O4 -> 0 | Z4: =(L4/26)*$O4 -> 4000000 | AA4: =IF($D4="HĐTV",M4/26*O4,(M4)) -> 400000 | AB4: =VLOOKUP($B4,'Bảng thông tin'!$B:$R,15,0)+VLOOKUP(B4,'Bảng thông tin'!$B:$Q,16,0) -> 0 | AC4: =+SUM(V4:AB4)+Q4+S4+U4 -> 26038462 | AD4: =X4 -> 2600000 | AE4: =IF($D4="HĐTV",0,Z4) -> 4000000 | AF4: =IF($D4="HĐTV",0,IF(AA4<=(5000000/12),AA4,AA4-(AA4-(5000000/12)))) -> 400000 | AG4: =+S4+U4 -> 1038462 | AH4: =+SUM(AD4:AG4) -> 8038462 | AI4: =IFERROR(IF($O4<14,0,$G4*17%),0) -> 3060000 | AJ4: =IFERROR(IF($O4<14,0,$G4*3%),0) -> 540000 | AK4: =IFERROR(IF($O4<14,0,$G4*1%),0) -> 180000 | AL4: =IFERROR(IF($O4<14,0,$G4*0.5%),0) -> 90000 | AM4: =IFERROR(SUM(AI4:AL4),0) -> 3870000 | AN4: =IFERROR($G4*2%,0) -> 360000 | AO4: =IFERROR(IF($O4<14,0,$G4*8%),0) -> 1440000 | AP4: =IFERROR(IF($O4<14,0,$G4*1.5%),0) -> 270000 | AQ4: =IFERROR(IF($O4<14,0,$G4*1%),0) -> 180000 | AR4: =SUM(AO4:AQ4) -> 1890000 | AS4: =+SUM($G$4)*0% -> 0 | AT4: =IF($D4="HĐTV",0,15500000) -> 15500000 | AV4: =+AU4*6200000 -> 0 | AW4: =+AT4+AV4 -> 15500000 | AX4: =ROUND(AC4-AH4,0) -> 18000000 | AY4: =IF(AX4-AW4-AR4-AS4<0,0,AX4-AW4-AR4-AS4) -> 610000 | AZ4: =IF(D4="HĐLĐ",IF(AY4<=10000000,AY4*5%,IF(AY4<=30000000,AY4*10%-500000,IF(AY4<=60000000,AY4*20%-3500000,IF(AY4<=100000000,AY4*30%-9500000,AY4*35%-14500000)))),AY4*10%) -> 30500 | BA4: =+VLOOKUP($B4,'Bảng thông tin'!$B:$R,16,0) -> 0 | BB4: =ROUND(AC4-AZ4-AR4-AS4-BA4,0) -> 24117962
A5: 2 | B5: QL002 | C5: =+VLOOKUP($B5,'Bảng thông tin'!$B$4:$R$1002,2,0) -> Nguyễn Diệp Anh Tuấn | D5: =+VLOOKUP($B5,'Bảng thông tin'!$B$4:$R$1002,3,0) -> HĐLĐ | E5: Giám Đốc | F5: =+VLOOKUP($B5,'Bảng thông tin'!$B$4:$R$1002,5,0) -> Ban giám đốc | G5: =+VLOOKUP($B5,'Bảng thông tin'!$B$4:$R$1002,7,0) -> 14000000 | H5: =+VLOOKUP($B5,'Bảng thông tin'!$B$4:$R$1002,8,0) -> 12000000 | I5: =+VLOOKUP($B5,'Bảng thông tin'!$B$4:$R$1002,9,0) -> 2000000 | J5: =+VLOOKUP($B5,'Bảng thông tin'!$B$4:$R$1002,10,0) -> 2000000 | K5: =+VLOOKUP($B5,'Bảng thông tin'!$B$4:$R$1002,11,0) -> 1000000 | L5: =+VLOOKUP($B5,'Bảng thông tin'!$B$4:$R$1002,12,0) -> 2600000 | M5: =+VLOOKUP($B5,'Bảng thông tin'!$B$4:$R$1002,13,0) -> 400000 | N5: =+VLOOKUP($B5,'Bảng thông tin'!$B$4:$R$1002,14,0) -> 20000000 | O5: =VLOOKUP($B5,BCC!$B$11:$AN$1032,35,0) -> 26 | P5: =VLOOKUP($B5,BCC!$B$11:$AN$1032,38,0)+VLOOKUP($B5,BCC!$B$11:$AN$1032,39,0) -> 0 | Q5: =+((H5+I5)/26)*P5 -> 0 | R5: =VLOOKUP($B5,BCC!$B$11:$AN$1032,36,0) -> 0 | S5: =ROUND(((H5+I5)/26)/8*R5*1.5,0) -> 0 | T5: =VLOOKUP($B5,BCC!$B$11:$AN$1032,37,0) -> 0 | U5: =ROUND(((H5+I5)/26)/8*T5*2,0) -> 0 | V5: =IF($D5="HĐTV",(H5/26)*$O5*0.85,(H5/26)*$O5) -> 12000000 | W5: =IF($D5="HĐTV",(I5/26)*$O5*0.85,($I5/26)*$O5) -> 2000000 | X5: =(J5/26)*$O5 -> 2000000 | Y5: =(K5/26)*$O5 -> 1000000 | Z5: =(L5/26)*$O5 -> 2600000 | AA5: =IF($D5="HĐTV",M5/26*O5,(M5)) -> 400000 | AB5: =VLOOKUP($B5,'Bảng thông tin'!$B:$R,15,0)+VLOOKUP(B5,'Bảng thông tin'!$B:$Q,16,0) -> 0 | AC5: =+SUM(V5:AB5)+Q5+S5+U5 -> 20000000 | AD5: =X5 -> 2000000 | AE5: =IF($D5="HĐTV",0,Z5) -> 2600000 | AF5: =IF($D5="HĐTV",0,IF(AA5<=(5000000/12),AA5,AA5-(AA5-(5000000/12)))) -> 400000 | AG5: =+S5+U5 -> 0 | AH5: =+SUM(AD5:AG5) -> 5000000 | AI5: =IFERROR(IF($O5<14,0,$G5*17%),0) -> 2380000 | AJ5: =IFERROR(IF($O5<14,0,$G5*3%),0) -> 420000 | AK5: =IFERROR(IF($O5<14,0,$G5*1%),0) -> 140000 | AL5: =IFERROR(IF($O5<14,0,$G5*0.5%),0) -> 70000 | AM5: =IFERROR(SUM(AI5:AL5),0) -> 3010000 | AN5: =IFERROR($G5*2%,0) -> 280000 | AO5: =IFERROR(IF($O5<14,0,$G5*8%),0) -> 1120000 | AP5: =IFERROR(IF($O5<14,0,$G5*1.5%),0) -> 210000 | AQ5: =IFERROR(IF($O5<14,0,$G5*1%),0) -> 140000 | AR5: =SUM(AO5:AQ5) -> 1470000 | AS5: =+SUM($G$4)*0% -> 0 | AT5: =IF($D5="HĐTV",0,15500000) -> 15500000 | AV5: =+AU5*6200000 -> 0 | AW5: =+AT5+AV5 -> 15500000 | AX5: =ROUND(AC5-AH5,0) -> 15000000 | AY5: =IF(AX5-AW5-AR5-AS5<0,0,AX5-AW5-AR5-AS5) -> 0 | AZ5: =IF(D5="HĐLĐ",IF(AY5<=10000000,AY5*5%,IF(AY5<=30000000,AY5*10%-500000,IF(AY5<=60000000,AY5*20%-3500000,IF(AY5<=100000000,AY5*30%-9500000,AY5*35%-14500000)))),AY5*10%) -> 0 | BA5: =+VLOOKUP($B5,'Bảng thông tin'!$B:$R,16,0) -> 0 | BB5: =ROUND(AC5-AZ5-AR5-AS5-BA5,0) -> 18530000
A6: 3 | B6: NV003 | C6: =+VLOOKUP($B6,'Bảng thông tin'!$B$4:$R$1002,2,0) -> Nguyễn Diệu Quý Chi | D6: =+VLOOKUP($B6,'Bảng thông tin'!$B$4:$R$1002,3,0) -> HĐLĐ | E6: Trưởng phòng | F6: Kinh doanh | G6: =+VLOOKUP($B6,'Bảng thông tin'!$B$4:$R$1002,7,0) -> 8500000 | H6: =+VLOOKUP($B6,'Bảng thông tin'!$B$4:$R$1002,8,0) -> 7500000 | I6: =+VLOOKUP($B6,'Bảng thông tin'!$B$4:$R$1002,9,0) -> 1000000 | J6: =+VLOOKUP($B6,'Bảng thông tin'!$B$4:$R$1002,10,0) -> 1800000 | K6: =+VLOOKUP($B6,'Bảng thông tin'!$B$4:$R$1002,11,0) -> 500000 | L6: =+VLOOKUP($B6,'Bảng thông tin'!$B$4:$R$1002,12,0) -> 400000 | M6: =+VLOOKUP($B6,'Bảng thông tin'!$B$4:$R$1002,13,0) -> 400000 | N6: =+VLOOKUP($B6,'Bảng thông tin'!$B$4:$R$1002,14,0) -> 11600000 | O6: =VLOOKUP($B6,BCC!$B$11:$AN$1032,35,0) -> 26 | P6: =VLOOKUP($B6,BCC!$B$11:$AN$1032,38,0)+VLOOKUP($B6,BCC!$B$11:$AN$1032,39,0) -> 0 | Q6: =+((H6+I6)/26)*P6 -> 0 | R6: =VLOOKUP($B6,BCC!$B$11:$AN$1032,36,0) -> 0 | S6: =ROUND(((H6+I6)/26)/8*R6*1.5,0) -> 0 | T6: =VLOOKUP($B6,BCC!$B$11:$AN$1032,37,0) -> 0 | U6: =ROUND(((H6+I6)/26)/8*T6*2,0) -> 0 | V6: =IF($D6="HĐTV",(H6/26)*$O6*0.85,(H6/26)*$O6) -> 7500000 | W6: =IF($D6="HĐTV",(I6/26)*$O6*0.85,($I6/26)*$O6) -> 1000000 | X6: =(J6/26)*$O6 -> 1800000 | Y6: =(K6/26)*$O6 -> 500000 | Z6: =(L6/26)*$O6 -> 400000 | AA6: =IF($D6="HĐTV",M6/26*O6,(M6)) -> 400000 | AB6: =VLOOKUP($B6,'Bảng thông tin'!$B:$R,15,0)+VLOOKUP(B6,'Bảng thông tin'!$B:$Q,16,0) -> 0 | AC6: =+SUM(V6:AB6)+Q6+S6+U6 -> 11600000 | AD6: =X6 -> 1800000 | AE6: =IF($D6="HĐTV",0,Z6) -> 400000 | AF6: =IF($D6="HĐTV",0,IF(AA6<=(5000000/12),AA6,AA6-(AA6-(5000000/12)))) -> 400000 | AG6: =+S6+U6 -> 0 | AH6: =+SUM(AD6:AG6) -> 2600000 | AI6: =IFERROR(IF($O6<14,0,$G6*17%),0) -> 1445000 | AJ6: =IFERROR(IF($O6<14,0,$G6*3%),0) -> 255000 | AK6: =IFERROR(IF($O6<14,0,$G6*1%),0) -> 85000 | AL6: =IFERROR(IF($O6<14,0,$G6*0.5%),0) -> 42500 | AM6: =IFERROR(SUM(AI6:AL6),0) -> 1827500 | AN6: =IFERROR($G6*2%,0) -> 170000 | AO6: =IFERROR(IF($O6<14,0,$G6*8%),0) -> 680000 | AP6: =IFERROR(IF($O6<14,0,$G6*1.5%),0) -> 127500 | AQ6: =IFERROR(IF($O6<14,0,$G6*1%),0) -> 85000 | AR6: =SUM(AO6:AQ6) -> 892500 | AS6: =+SUM($G$4)*0% -> 0 | AT6: =IF($D6="HĐTV",0,15500000) -> 15500000 | AV6: =+AU6*6200000 -> 0 | AW6: =+AT6+AV6 -> 15500000 | AX6: =ROUND(AC6-AH6,0) -> 9000000 | AY6: =IF(AX6-AW6-AR6-AS6<0,0,AX6-AW6-AR6-AS6) -> 0 | AZ6: =IF(D6="HĐLĐ",IF(AY6<=10000000,AY6*5%,IF(AY6<=30000000,AY6*10%-500000,IF(AY6<=60000000,AY6*20%-3500000,IF(AY6<=100000000,AY6*30%-9500000,AY6*35%-14500000)))),AY6*10%) -> 0 | BA6: =+VLOOKUP($B6,'Bảng thông tin'!$B:$R,16,0) -> 0 | BB6: =ROUND(AC6-AZ6-AR6-AS6-BA6,0) -> 10707500
A7: 4 | B7: NV004 | C7: =+VLOOKUP($B7,'Bảng thông tin'!$B$4:$R$1002,2,0) -> Phạm Đăng Anh Thảo | D7: =+VLOOKUP($B7,'Bảng thông tin'!$B$4:$R$1002,3,0) -> HĐLĐ | E7: Phó phòng | F7: Kinh doanh | G7: =+VLOOKUP($B7,'Bảng thông tin'!$B$4:$R$1002,7,0) -> 8000000 | H7: =+VLOOKUP($B7,'Bảng thông tin'!$B$4:$R$1002,8,0) -> 7000000 | I7: =+VLOOKUP($B7,'Bảng thông tin'!$B$4:$R$1002,9,0) -> 1000000 | J7: =+VLOOKUP($B7,'Bảng thông tin'!$B$4:$R$1002,10,0) -> 1300000 | K7: =+VLOOKUP($B7,'Bảng thông tin'!$B$4:$R$1002,11,0) -> 500000 | L7: =+VLOOKUP($B7,'Bảng thông tin'!$B$4:$R$1002,12,0) -> 400000 | M7: =+VLOOKUP($B7,'Bảng thông tin'!$B$4:$R$1002,13,0) -> 400000 | N7: =+VLOOKUP($B7,'Bảng thông tin'!$B$4:$R$1002,14,0) -> 10600000 | O7: =VLOOKUP($B7,BCC!$B$11:$AN$1032,35,0) -> 25 | P7: =VLOOKUP($B7,BCC!$B$11:$AN$1032,38,0)+VLOOKUP($B7,BCC!$B$11:$AN$1032,39,0) -> 1 | Q7: =+((H7+I7)/26)*P7 -> 307692.31 | R7: =VLOOKUP($B7,BCC!$B$11:$AN$1032,36,0) -> 0 | S7: =ROUND(((H7+I7)/26)/8*R7*1.5,0) -> 0 | T7: =VLOOKUP($B7,BCC!$B$11:$AN$1032,37,0) -> 0 | U7: =ROUND(((H7+I7)/26)/8*T7*2,0) -> 0 | V7: =IF($D7="HĐTV",(H7/26)*$O7*0.85,(H7/26)*$O7) -> 6730769.2 | W7: =IF($D7="HĐTV",(I7/26)*$O7*0.85,($I7/26)*$O7) -> 961538.46 | X7: =(J7/26)*$O7 -> 1250000 | Y7: =(K7/26)*$O7 -> 480769.23 | Z7: =(L7/26)*$O7 -> 384615.38 | AA7: =IF($D7="HĐTV",M7/26*O7,(M7)) -> 400000 | AB7: =VLOOKUP($B7,'Bảng thông tin'!$B:$R,15,0)+VLOOKUP(B7,'Bảng thông tin'!$B:$Q,16,0) -> 0 | AC7: =+SUM(V7:AB7)+Q7+S7+U7 -> 10515385 | AD7: =X7 -> 1250000 | AE7: =IF($D7="HĐTV",0,Z7) -> 384615.38 | AF7: =IF($D7="HĐTV",0,IF(AA7<=(5000000/12),AA7,AA7-(AA7-(5000000/12)))) -> 400000 | AG7: =+S7+U7 -> 0 | AH7: =+SUM(AD7:AG7) -> 2034615.4 | AI7: =IFERROR(IF($O7<14,0,$G7*17%),0) -> 1360000 | AJ7: =IFERROR(IF($O7<14,0,$G7*3%),0) -> 240000 | AK7: =IFERROR(IF($O7<14,0,$G7*1%),0) -> 80000 | AL7: =IFERROR(IF($O7<14,0,$G7*0.5%),0) -> 40000 | AM7: =IFERROR(SUM(AI7:AL7),0) -> 1720000 | AN7: =IFERROR($G7*2%,0) -> 160000 | AO7: =IFERROR(IF($O7<14,0,$G7*8%),0) -> 640000 | AP7: =IFERROR(IF($O7<14,0,$G7*1.5%),0) -> 120000 | AQ7: =IFERROR(IF($O7<14,0,$G7*1%),0) -> 80000 | AR7: =SUM(AO7:AQ7) -> 840000 | AS7: =+SUM($G$4)*0% -> 0 | AT7: =IF($D7="HĐTV",0,15500000) -> 15500000 | AV7: =+AU7*6200000 -> 0 | AW7: =+AT7+AV7 -> 15500000 | AX7: =ROUND(AC7-AH7,0) -> 8480769 | AY7: =IF(AX7-AW7-AR7-AS7<0,0,AX7-AW7-AR7-AS7) -> 0 | AZ7: =IF(D7="HĐLĐ",IF(AY7<=10000000,AY7*5%,IF(AY7<=30000000,AY7*10%-500000,IF(AY7<=60000000,AY7*20%-3500000,IF(AY7<=100000000,AY7*30%-9500000,AY7*35%-14500000)))),AY7*10%) -> 0 | BA7: =+VLOOKUP($B7,'Bảng thông tin'!$B:$R,16,0) -> 0 | BB7: =ROUND(AC7-AZ7-AR7-AS7-BA7,0) -> 9675385
A8: 5 | B8: NV011 | C8: =+VLOOKUP($B8,'Bảng thông tin'!$B$4:$R$1002,2,0) -> Nguyễn Thành Long | D8: =+VLOOKUP($B8,'Bảng thông tin'!$B$4:$R$1002,3,0) -> HĐLĐ | E8: Nhân viên | F8: Kinh doanh | G8: =+VLOOKUP($B8,'Bảng thông tin'!$B$4:$R$1002,7,0) -> 7000000 | H8: =+VLOOKUP($B8,'Bảng thông tin'!$B$4:$R$1002,8,0) -> 6500000 | I8: =+VLOOKUP($B8,'Bảng thông tin'!$B$4:$R$1002,9,0) -> 500000 | J8: =+VLOOKUP($B8,'Bảng thông tin'!$B$4:$R$1002,10,0) -> 1000000 | K8: =+VLOOKUP($B8,'Bảng thông tin'!$B$4:$R$1002,11,0) -> 500000 | L8: =+VLOOKUP($B8,'Bảng thông tin'!$B$4:$R$1002,12,0) -> 300000 | M8: =+VLOOKUP($B8,'Bảng thông tin'!$B$4:$R$1002,13,0) -> 400000 | N8: =+VLOOKUP($B8,'Bảng thông tin'!$B$4:$R$1002,14,0) -> 9200000 | O8: =VLOOKUP($B8,BCC!$B$11:$AN$1032,35,0) -> 26 | P8: =VLOOKUP($B8,BCC!$B$11:$AN$1032,38,0)+VLOOKUP($B8,BCC!$B$11:$AN$1032,39,0) -> 0 | Q8: =+((H8+I8)/26)*P8 -> 0 | R8: =VLOOKUP($B8,BCC!$B$11:$AN$1032,36,0) -> 8 | S8: =ROUND(((H8+I8)/26)/8*R8*1.5,0) -> 403846 | T8: =VLOOKUP($B8,BCC!$B$11:$AN$1032,37,0) -> 16 | U8: =ROUND(((H8+I8)/26)/8*T8*2,0) -> 1076923 | V8: =IF($D8="HĐTV",(H8/26)*$O8*0.85,(H8/26)*$O8) -> 6500000 | W8: =IF($D8="HĐTV",(I8/26)*$O8*0.85,($I8/26)*$O8) -> 500000 | X8: =(J8/26)*$O8 -> 1000000 | Y8: =(K8/26)*$O8 -> 500000 | Z8: =(L8/26)*$O8 -> 300000 | AA8: =IF($D8="HĐTV",M8/26*O8,(M8)) -> 400000 | AB8: =VLOOKUP($B8,'Bảng thông tin'!$B:$R,15,0)+VLOOKUP(B8,'Bảng thông tin'!$B:$Q,16,0) -> 0 | AC8: =+SUM(V8:AB8)+Q8+S8+U8 -> 10680769 | AD8: =X8 -> 1000000 | AE8: =IF($D8="HĐTV",0,Z8) -> 300000 | AF8: =IF($D8="HĐTV",0,IF(AA8<=(5000000/12),AA8,AA8-(AA8-(5000000/12)))) -> 400000 | AG8: =+S8+U8 -> 1480769 | AH8: =+SUM(AD8:AG8) -> 3180769 | AI8: =IFERROR(IF($O8<14,0,$G8*17%),0) -> 1190000 | AJ8: =IFERROR(IF($O8<14,0,$G8*3%),0) -> 210000 | AK8: =IFERROR(IF($O8<14,0,$G8*1%),0) -> 70000 | AL8: =IFERROR(IF($O8<14,0,$G8*0.5%),0) -> 35000 | AM8: =IFERROR(SUM(AI8:AL8),0) -> 1505000 | AN8: =IFERROR($G8*2%,0) -> 140000 | AO8: =IFERROR(IF($O8<14,0,$G8*8%),0) -> 560000 | AP8: =IFERROR(IF($O8<14,0,$G8*1.5%),0) -> 105000 | AQ8: =IFERROR(IF($O8<14,0,$G8*1%),0) -> 70000 | AR8: =SUM(AO8:AQ8) -> 735000 | AS8: =+SUM($G$4)*0% -> 0 | AT8: =IF($D8="HĐTV",0,15500000) -> 15500000 | AV8: =+AU8*6200000 -> 0 | AW8: =+AT8+AV8 -> 15500000 | AX8: =ROUND(AC8-AH8,0) -> 7500000 | AY8: =IF(AX8-AW8-AR8-AS8<0,0,AX8-AW8-AR8-AS8) -> 0 | AZ8: =IF(D8="HĐLĐ",IF(AY8<=10000000,AY8*5%,IF(AY8<=30000000,AY8*10%-500000,IF(AY8<=60000000,AY8*20%-3500000,IF(AY8<=100000000,AY8*30%-9500000,AY8*35%-14500000)))),AY8*10%) -> 0 | BA8: =+VLOOKUP($B8,'Bảng thông tin'!$B:$R,16,0) -> 0 | BB8: =ROUND(AC8-AZ8-AR8-AS8-BA8,0) -> 9945769
A9: 6 | B9: NV012 | C9: =+VLOOKUP($B9,'Bảng thông tin'!$B$4:$R$1002,2,0) -> Nguyễn Thị Đài Trang | D9: =+VLOOKUP($B9,'Bảng thông tin'!$B$4:$R$1002,3,0) -> HĐLĐ | E9: Nhân viên | F9: Kinh doanh | G9: =+VLOOKUP($B9,'Bảng thông tin'!$B$4:$R$1002,7,0) -> 7000000 | H9: =+VLOOKUP($B9,'Bảng thông tin'!$B$4:$R$1002,8,0) -> 6500000 | I9: =+VLOOKUP($B9,'Bảng thông tin'!$B$4:$R$1002,9,0) -> 500000 | J9: =+VLOOKUP($B9,'Bảng thông tin'!$B$4:$R$1002,10,0) -> 1000000 | K9: =+VLOOKUP($B9,'Bảng thông tin'!$B$4:$R$1002,11,0) -> 500000 | L9: =+VLOOKUP($B9,'Bảng thông tin'!$B$4:$R$1002,12,0) -> 300000 | M9: =+VLOOKUP($B9,'Bảng thông tin'!$B$4:$R$1002,13,0) -> 400000 | N9: =+VLOOKUP($B9,'Bảng thông tin'!$B$4:$R$1002,14,0) -> 9200000 | O9: =VLOOKUP($B9,BCC!$B$11:$AN$1032,35,0) -> 26 | P9: =VLOOKUP($B9,BCC!$B$11:$AN$1032,38,0)+VLOOKUP($B9,BCC!$B$11:$AN$1032,39,0) -> 0 | Q9: =+((H9+I9)/26)*P9 -> 0 | R9: =VLOOKUP($B9,BCC!$B$11:$AN$1032,36,0) -> 25.95 | S9: =ROUND(((H9+I9)/26)/8*R9*1.5,0) -> 1309976 | T9: =VLOOKUP($B9,BCC!$B$11:$AN$1032,37,0) -> 8 | U9: =ROUND(((H9+I9)/26)/8*T9*2,0) -> 538462 | V9: =IF($D9="HĐTV",(H9/26)*$O9*0.85,(H9/26)*$O9) -> 6500000 | W9: =IF($D9="HĐTV",(I9/26)*$O9*0.85,($I9/26)*$O9) -> 500000 | X9: =(J9/26)*$O9 -> 1000000 | Y9: =(K9/26)*$O9 -> 500000 | Z9: =(L9/26)*$O9 -> 300000 | AA9: =IF($D9="HĐTV",M9/26*O9,(M9)) -> 400000 | AB9: =VLOOKUP($B9,'Bảng thông tin'!$B:$R,15,0)+VLOOKUP(B9,'Bảng thông tin'!$B:$Q,16,0) -> 0 | AC9: =+SUM(V9:AB9)+Q9+S9+U9 -> 11048438 | AD9: =X9 -> 1000000 | AE9: =IF($D9="HĐTV",0,Z9) -> 300000 | AF9: =IF($D9="HĐTV",0,IF(AA9<=(5000000/12),AA9,AA9-(AA9-(5000000/12)))) -> 400000 | AG9: =+S9+U9 -> 1848438 | AH9: =+SUM(AD9:AG9) -> 3548438 | AI9: =IFERROR(IF($O9<14,0,$G9*17%),0) -> 1190000 | AJ9: =IFERROR(IF($O9<14,0,$G9*3%),0) -> 210000 | AK9: =IFERROR(IF($O9<14,0,$G9*1%),0) -> 70000 | AL9: =IFERROR(IF($O9<14,0,$G9*0.5%),0) -> 35000 | AM9: =IFERROR(SUM(AI9:AL9),0) -> 1505000 | AN9: =IFERROR($G9*2%,0) -> 140000 | AO9: =IFERROR(IF($O9<14,0,$G9*8%),0) -> 560000 | AP9: =IFERROR(IF($O9<14,0,$G9*1.5%),0) -> 105000 | AQ9: =IFERROR(IF($O9<14,0,$G9*1%),0) -> 70000 | AR9: =SUM(AO9:AQ9) -> 735000 | AS9: =+SUM($G$4)*0% -> 0 | AT9: =IF($D9="HĐTV",0,15500000) -> 15500000 | AV9: =+AU9*6200000 -> 0 | AW9: =+AT9+AV9 -> 15500000 | AX9: =ROUND(AC9-AH9,0) -> 7500000 | AY9: =IF(AX9-AW9-AR9-AS9<0,0,AX9-AW9-AR9-AS9) -> 0 | AZ9: =IF(D9="HĐLĐ",IF(AY9<=10000000,AY9*5%,IF(AY9<=30000000,AY9*10%-500000,IF(AY9<=60000000,AY9*20%-3500000,IF(AY9<=100000000,AY9*30%-9500000,AY9*35%-14500000)))),AY9*10%) -> 0 | BA9: =+VLOOKUP($B9,'Bảng thông tin'!$B:$R,16,0) -> 0 | BB9: =ROUND(AC9-AZ9-AR9-AS9-BA9,0) -> 10313438
A10: 7 | B10: NV027 | C10: =+VLOOKUP($B10,'Bảng thông tin'!$B$4:$R$1002,2,0) -> Lê Thị Hiếu | D10: =+VLOOKUP($B10,'Bảng thông tin'!$B$4:$R$1002,3,0) -> HĐLĐ | E10: Nhân viên | F10: Kinh doanh | G10: =+VLOOKUP($B10,'Bảng thông tin'!$B$4:$R$1002,7,0) -> 7000000 | H10: =+VLOOKUP($B10,'Bảng thông tin'!$B$4:$R$1002,8,0) -> 6500000 | I10: =+VLOOKUP($B10,'Bảng thông tin'!$B$4:$R$1002,9,0) -> 500000 | J10: =+VLOOKUP($B10,'Bảng thông tin'!$B$4:$R$1002,10,0) -> 1000000 | K10: =+VLOOKUP($B10,'Bảng thông tin'!$B$4:$R$1002,11,0) -> 500000 | L10: =+VLOOKUP($B10,'Bảng thông tin'!$B$4:$R$1002,12,0) -> 300000 | M10: =+VLOOKUP($B10,'Bảng thông tin'!$B$4:$R$1002,13,0) -> 400000 | N10: =+VLOOKUP($B10,'Bảng thông tin'!$B$4:$R$1002,14,0) -> 9200000 | O10: =VLOOKUP($B10,BCC!$B$11:$AN$1032,35,0) -> 26 | P10: =VLOOKUP($B10,BCC!$B$11:$AN$1032,38,0)+VLOOKUP($B10,BCC!$B$11:$AN$1032,39,0) -> 0 | Q10: =+((H10+I10)/26)*P10 -> 0 | R10: =VLOOKUP($B10,BCC!$B$11:$AN$1032,36,0) -> 8.25 | S10: =ROUND(((H10+I10)/26)/8*R10*1.5,0) -> 416466 | T10: =VLOOKUP($B10,BCC!$B$11:$AN$1032,37,0) -> 16.58 | U10: =ROUND(((H10+I10)/26)/8*T10*2,0) -> 1115962 | V10: =IF($D10="HĐTV",(H10/26)*$O10*0.85,(H10/26)*$O10) -> 6500000 | W10: =IF($D10="HĐTV",(I10/26)*$O10*0.85,($I10/26)*$O10) -> 500000 | X10: =(J10/26)*$O10 -> 1000000 | Y10: =(K10/26)*$O10 -> 500000 | Z10: =(L10/26)*$O10 -> 300000 | AA10: =IF($D10="HĐTV",M10/26*O10,(M10)) -> 400000 | AB10: =VLOOKUP($B10,'Bảng thông tin'!$B:$R,15,0)+VLOOKUP(B10,'Bảng thông tin'!$B:$Q,16,0) -> 0 | AC10: =+SUM(V10:AB10)+Q10+S10+U10 -> 10732428 | AD10: =X10 -> 1000000 | AE10: =IF($D10="HĐTV",0,Z10) -> 300000 | AF10: =IF($D10="HĐTV",0,IF(AA10<=(5000000/12),AA10,AA10-(AA10-(5000000/12)))) -> 400000 | AG10: =+S10+U10 -> 1532428 | AH10: =+SUM(AD10:AG10) -> 3232428 | AI10: =IFERROR(IF($O10<14,0,$G10*17%),0) -> 1190000 | AJ10: =IFERROR(IF($O10<14,0,$G10*3%),0) -> 210000 | AK10: =IFERROR(IF($O10<14,0,$G10*1%),0) -> 70000 | AL10: =IFERROR(IF($O10<14,0,$G10*0.5%),0) -> 35000 | AM10: =IFERROR(SUM(AI10:AL10),0) -> 1505000 | AN10: =IFERROR($G10*2%,0) -> 140000 | AO10: =IFERROR(IF($O10<14,0,$G10*8%),0) -> 560000 | AP10: =IFERROR(IF($O10<14,0,$G10*1.5%),0) -> 105000 | AQ10: =IFERROR(IF($O10<14,0,$G10*1%),0) -> 70000 | AR10: =SUM(AO10:AQ10) -> 735000 | AS10: =+SUM($G$4)*0% -> 0 | AT10: =IF($D10="HĐTV",0,15500000) -> 15500000 | AV10: =+AU10*6200000 -> 0 | AW10: =+AT10+AV10 -> 15500000 | AX10: =ROUND(AC10-AH10,0) -> 7500000 | AY10: =IF(AX10-AW10-AR10-AS10<0,0,AX10-AW10-AR10-AS10) -> 0 | AZ10: =IF(D10="HĐLĐ",IF(AY10<=10000000,AY10*5%,IF(AY10<=30000000,AY10*10%-500000,IF(AY10<=60000000,AY10*20%-3500000,IF(AY10<=100000000,AY10*30%-9500000,AY10*35%-14500000)))),AY10*10%) -> 0 | BA10: =+VLOOKUP($B10,'Bảng thông tin'!$B:$R,16,0) -> 0 | BB10: =ROUND(AC10-AZ10-AR10-AS10-BA10,0) -> 9997428
A11: 8 | B11: NV030 | C11: =+VLOOKUP($B11,'Bảng thông tin'!$B$4:$R$1002,2,0) -> Vương Thị Ngọc Như | D11: =+VLOOKUP($B11,'Bảng thông tin'!$B$4:$R$1002,3,0) -> HĐLĐ | E11: Nhân viên tư vấn | F11: Kinh doanh | G11: =+VLOOKUP($B11,'Bảng thông tin'!$B$4:$R$1002,7,0) -> 6000000 | H11: =+VLOOKUP($B11,'Bảng thông tin'!$B$4:$R$1002,8,0) -> 5500000 | I11: =+VLOOKUP($B11,'Bảng thông tin'!$B$4:$R$1002,9,0) -> 500000 | J11: =+VLOOKUP($B11,'Bảng thông tin'!$B$4:$R$1002,10,0) -> 1000000 | K11: =+VLOOKUP($B11,'Bảng thông tin'!$B$4:$R$1002,11,0) -> 0 | L11: =+VLOOKUP($B11,'Bảng thông tin'!$B$4:$R$1002,12,0) -> 200000 | M11: =+VLOOKUP($B11,'Bảng thông tin'!$B$4:$R$1002,13,0) -> 300000 | N11: =+VLOOKUP($B11,'Bảng thông tin'!$B$4:$R$1002,14,0) -> 7500000 | O11: =VLOOKUP($B11,BCC!$B$11:$AN$1032,35,0) -> 26 | P11: =VLOOKUP($B11,BCC!$B$11:$AN$1032,38,0)+VLOOKUP($B11,BCC!$B$11:$AN$1032,39,0) -> 2 | Q11: =+((H11+I11)/26)*P11 -> 461538.46 | R11: =VLOOKUP($B11,BCC!$B$11:$AN$1032,36,0) -> 38.83 | S11: =ROUND(((H11+I11)/26)/8*R11*1.5,0) -> 1680144 | T11: =VLOOKUP($B11,BCC!$B$11:$AN$1032,37,0) -> 0 | U11: =ROUND(((H11+I11)/26)/8*T11*2,0) -> 0 | V11: =IF($D11="HĐTV",(H11/26)*$O11*0.85,(H11/26)*$O11) -> 5500000 | W11: =IF($D11="HĐTV",(I11/26)*$O11*0.85,($I11/26)*$O11) -> 500000 | X11: =(J11/26)*$O11 -> 1000000 | Y11: =(K11/26)*$O11 -> 0 | Z11: =(L11/26)*$O11 -> 200000 | AA11: =IF($D11="HĐTV",M11/26*O11,(M11)) -> 300000 | AB11: =VLOOKUP($B11,'Bảng thông tin'!$B:$R,15,0)+VLOOKUP(B11,'Bảng thông tin'!$B:$Q,16,0) -> 0 | AC11: =+SUM(V11:AB11)+Q11+S11+U11 -> 9641682.5 | AD11: =X11 -> 1000000 | AE11: =IF($D11="HĐTV",0,Z11) -> 200000 | AF11: =IF($D11="HĐTV",0,IF(AA11<=(5000000/12),AA11,AA11-(AA11-(5000000/12)))) -> 300000 | AG11: =+S11+U11 -> 1680144 | AH11: =+SUM(AD11:AG11) -> 3180144 | AI11: =IFERROR(IF($O11<14,0,$G11*17%),0) -> 1020000 | AJ11: =IFERROR(IF($O11<14,0,$G11*3%),0) -> 180000 | AK11: =IFERROR(IF($O11<14,0,$G11*1%),0) -> 60000 | AL11: =IFERROR(IF($O11<14,0,$G11*0.5%),0) -> 30000 | AM11: =IFERROR(SUM(AI11:AL11),0) -> 1290000 | AN11: =IFERROR($G11*2%,0) -> 120000 | AO11: =IFERROR(IF($O11<14,0,$G11*8%),0) -> 480000 | AP11: =IFERROR(IF($O11<14,0,$G11*1.5%),0) -> 90000 | AQ11: =IFERROR(IF($O11<14,0,$G11*1%),0) -> 60000 | AR11: =SUM(AO11:AQ11) -> 630000 | AS11: =+SUM($G$4)*0% -> 0 | AT11: =IF($D11="HĐTV",0,15500000) -> 15500000 | AV11: =+AU11*6200000 -> 0 | AW11: =+AT11+AV11 -> 15500000 | AX11: =ROUND(AC11-AH11,0) -> 6461538 | AY11: =IF(AX11-AW11-AR11-AS11<0,0,AX11-AW11-AR11-AS11) -> 0 | AZ11: =IF(D11="HĐLĐ",IF(AY11<=10000000,AY11*5%,IF(AY11<=30000000,AY11*10%-500000,IF(AY11<=60000000,AY11*20%-3500000,IF(AY11<=100000000,AY11*30%-9500000,AY11*35%-14500000)))),AY11*10%) -> 0 | BA11: =+VLOOKUP($B11,'Bảng thông tin'!$B:$R,16,0) -> 0 | BB11: =ROUND(AC11-AZ11-AR11-AS11-BA11,0) -> 9011682
A12: 9 | B12: NV001 | C12: =+VLOOKUP($B12,'Bảng thông tin'!$B$4:$R$1002,2,0) -> Nguyễn Thị Châu Loan | D12: =+VLOOKUP($B12,'Bảng thông tin'!$B$4:$R$1002,3,0) -> HĐLĐ | E12: Trưởng phòng | F12: Logistic | G12: =+VLOOKUP($B12,'Bảng thông tin'!$B$4:$R$1002,7,0) -> 8500000 | H12: =+VLOOKUP($B12,'Bảng thông tin'!$B$4:$R$1002,8,0) -> 7500000 | I12: =+VLOOKUP($B12,'Bảng thông tin'!$B$4:$R$1002,9,0) -> 1000000 | J12: =+VLOOKUP($B12,'Bảng thông tin'!$B$4:$R$1002,10,0) -> 1800000 | K12: =+VLOOKUP($B12,'Bảng thông tin'!$B$4:$R$1002,11,0) -> 500000 | L12: =+VLOOKUP($B12,'Bảng thông tin'!$B$4:$R$1002,12,0) -> 400000 | M12: =+VLOOKUP($B12,'Bảng thông tin'!$B$4:$R$1002,13,0) -> 400000 | N12: =+VLOOKUP($B12,'Bảng thông tin'!$B$4:$R$1002,14,0) -> 11600000 | O12: =VLOOKUP($B12,BCC!$B$11:$AN$1032,35,0) -> 24 | P12: =VLOOKUP($B12,BCC!$B$11:$AN$1032,38,0)+VLOOKUP($B12,BCC!$B$11:$AN$1032,39,0) -> 2 | Q12: =+((H12+I12)/26)*P12 -> 653846.15 | R12: =VLOOKUP($B12,BCC!$B$11:$AN$1032,36,0) -> 0 | S12: =ROUND(((H12+I12)/26)/8*R12*1.5,0) -> 0 | T12: =VLOOKUP($B12,BCC!$B$11:$AN$1032,37,0) -> 0 | U12: =ROUND(((H12+I12)/26)/8*T12*2,0) -> 0 | V12: =IF($D12="HĐTV",(H12/26)*$O12*0.85,(H12/26)*$O12) -> 6923076.9 | W12: =IF($D12="HĐTV",(I12/26)*$O12*0.85,($I12/26)*$O12) -> 923076.92 | X12: =(J12/26)*$O12 -> 1661538.5 | Y12: =(K12/26)*$O12 -> 461538.46 | Z12: =(L12/26)*$O12 -> 369230.77 | AA12: =IF($D12="HĐTV",M12/26*O12,(M12)) -> 400000 | AB12: =VLOOKUP($B12,'Bảng thông tin'!$B:$R,15,0)+VLOOKUP(B12,'Bảng thông tin'!$B:$Q,16,0) -> 0 | AC12: =+SUM(V12:AB12)+Q12+S12+U12 -> 11392308 | AD12: =X12 -> 1661538.5 | AE12: =IF($D12="HĐTV",0,Z12) -> 369230.77 | AF12: =IF($D12="HĐTV",0,IF(AA12<=(5000000/12),AA12,AA12-(AA12-(5000000/12)))) -> 400000 | AG12: =+S12+U12 -> 0 | AH12: =+SUM(AD12:AG12) -> 2430769.2 | AI12: =IFERROR(IF($O12<14,0,$G12*17%),0) -> 1445000 | AJ12: =IFERROR(IF($O12<14,0,$G12*3%),0) -> 255000 | AK12: =IFERROR(IF($O12<14,0,$G12*1%),0) -> 85000 | AL12: =IFERROR(IF($O12<14,0,$G12*0.5%),0) -> 42500 | AM12: =IFERROR(SUM(AI12:AL12),0) -> 1827500 | AN12: =IFERROR($G12*2%,0) -> 170000 | AO12: =IFERROR(IF($O12<14,0,$G12*8%),0) -> 680000 | AP12: =IFERROR(IF($O12<14,0,$G12*1.5%),0) -> 127500 | AQ12: =IFERROR(IF($O12<14,0,$G12*1%),0) -> 85000 | AR12: =SUM(AO12:AQ12) -> 892500 | AS12: =+SUM($G$4)*0% -> 0 | AT12: =IF($D12="HĐTV",0,15500000) -> 15500000 | AV12: =+AU12*6200000 -> 0 | AW12: =+AT12+AV12 -> 15500000 | AX12: =ROUND(AC12-AH12,0) -> 8961538 | AY12: =IF(AX12-AW12-AR12-AS12<0,0,AX12-AW12-AR12-AS12) -> 0 | AZ12: =IF(D12="HĐLĐ",IF(AY12<=10000000,AY12*5%,IF(AY12<=30000000,AY12*10%-500000,IF(AY12<=60000000,AY12*20%-3500000,IF(AY12<=100000000,AY12*30%-9500000,AY12*35%-14500000)))),AY12*10%) -> 0 | BA12: =+VLOOKUP($B12,'Bảng thông tin'!$B:$R,16,0) -> 0 | BB12: =ROUND(AC12-AZ12-AR12-AS12-BA12,0) -> 10499808
A13: 10 | B13: NV005 | C13: =+VLOOKUP($B13,'Bảng thông tin'!$B$4:$R$1002,2,0) -> Nguyễn Văn Thái | D13: =+VLOOKUP($B13,'Bảng thông tin'!$B$4:$R$1002,3,0) -> HĐLĐ | E13: Phó phòng | F13: Logistic | G13: =+VLOOKUP($B13,'Bảng thông tin'!$B$4:$R$1002,7,0) -> 8000000 | H13: =+VLOOKUP($B13,'Bảng thông tin'!$B$4:$R$1002,8,0) -> 7000000 | I13: =+VLOOKUP($B13,'Bảng thông tin'!$B$4:$R$1002,9,0) -> 1000000 | J13: =+VLOOKUP($B13,'Bảng thông tin'!$B$4:$R$1002,10,0) -> 1300000 | K13: =+VLOOKUP($B13,'Bảng thông tin'!$B$4:$R$1002,11,0) -> 500000 | L13: =+VLOOKUP($B13,'Bảng thông tin'!$B$4:$R$1002,12,0) -> 400000 | M13: =+VLOOKUP($B13,'Bảng thông tin'!$B$4:$R$1002,13,0) -> 400000 | N13: =+VLOOKUP($B13,'Bảng thông tin'!$B$4:$R$1002,14,0) -> 10600000 | O13: =VLOOKUP($B13,BCC!$B$11:$AN$1032,35,0) -> 24 | P13: =VLOOKUP($B13,BCC!$B$11:$AN$1032,38,0)+VLOOKUP($B13,BCC!$B$11:$AN$1032,39,0) -> 2 | Q13: =+((H13+I13)/26)*P13 -> 615384.62 | R13: =VLOOKUP($B13,BCC!$B$11:$AN$1032,36,0) -> 0 | S13: =ROUND(((H13+I13)/26)/8*R13*1.5,0) -> 0 | T13: =VLOOKUP($B13,BCC!$B$11:$AN$1032,37,0) -> 8 | U13: =ROUND(((H13+I13)/26)/8*T13*2,0) -> 615385 | V13: =IF($D13="HĐTV",(H13/26)*$O13*0.85,(H13/26)*$O13) -> 6461538.5 | W13: =IF($D13="HĐTV",(I13/26)*$O13*0.85,($I13/26)*$O13) -> 923076.92 | X13: =(J13/26)*$O13 -> 1200000 | Y13: =(K13/26)*$O13 -> 461538.46 | Z13: =(L13/26)*$O13 -> 369230.77 | AA13: =IF($D13="HĐTV",M13/26*O13,(M13)) -> 400000 | AB13: =VLOOKUP($B13,'Bảng thông tin'!$B:$R,15,0)+VLOOKUP(B13,'Bảng thông tin'!$B:$Q,16,0) -> 0 | AC13: =+SUM(V13:AB13)+Q13+S13+U13 -> 11046154 | AD13: =X13 -> 1200000 | AE13: =IF($D13="HĐTV",0,Z13) -> 369230.77 | AF13: =IF($D13="HĐTV",0,IF(AA13<=(5000000/12),AA13,AA13-(AA13-(5000000/12)))) -> 400000 | AG13: =+S13+U13 -> 615385 | AH13: =+SUM(AD13:AG13) -> 2584615.8 | AI13: =IFERROR(IF($O13<14,0,$G13*17%),0) -> 1360000 | AJ13: =IFERROR(IF($O13<14,0,$G13*3%),0) -> 240000 | AK13: =IFERROR(IF($O13<14,0,$G13*1%),0) -> 80000 | AL13: =IFERROR(IF($O13<14,0,$G13*0.5%),0) -> 40000 | AM13: =IFERROR(SUM(AI13:AL13),0) -> 1720000 | AN13: =IFERROR($G13*2%,0) -> 160000 | AO13: =IFERROR(IF($O13<14,0,$G13*8%),0) -> 640000 | AP13: =IFERROR(IF($O13<14,0,$G13*1.5%),0) -> 120000 | AQ13: =IFERROR(IF($O13<14,0,$G13*1%),0) -> 80000 | AR13: =SUM(AO13:AQ13) -> 840000 | AS13: =+SUM($G$4)*0% -> 0 | AT13: =IF($D13="HĐTV",0,15500000) -> 15500000 | AV13: =+AU13*6200000 -> 0 | AW13: =+AT13+AV13 -> 15500000 | AX13: =ROUND(AC13-AH13,0) -> 8461538 | AY13: =IF(AX13-AW13-AR13-AS13<0,0,AX13-AW13-AR13-AS13) -> 0 | AZ13: =IF(D13="HĐLĐ",IF(AY13<=10000000,AY13*5%,IF(AY13<=30000000,AY13*10%-500000,IF(AY13<=60000000,AY13*20%-3500000,IF(AY13<=100000000,AY13*30%-9500000,AY13*35%-14500000)))),AY13*10%) -> 0 | BA13: =+VLOOKUP($B13,'Bảng thông tin'!$B:$R,16,0) -> 0 | BB13: =ROUND(AC13-AZ13-AR13-AS13-BA13,0) -> 10206154
A14: 11 | B14: NV010 | C14: =+VLOOKUP($B14,'Bảng thông tin'!$B$4:$R$1002,2,0) -> Lê Hữu Thọ | D14: =+VLOOKUP($B14,'Bảng thông tin'!$B$4:$R$1002,3,0) -> HĐLĐ | E14: Thủ kho trưởng | F14: Logistic | G14: =+VLOOKUP($B14,'Bảng thông tin'!$B$4:$R$1002,7,0) -> 8000000 | H14: =+VLOOKUP($B14,'Bảng thông tin'!$B$4:$R$1002,8,0) -> 7000000 | I14: =+VLOOKUP($B14,'Bảng thông tin'!$B$4:$R$1002,9,0) -> 1000000 | J14: =+VLOOKUP($B14,'Bảng thông tin'!$B$4:$R$1002,10,0) -> 1300000 | K14: =+VLOOKUP($B14,'Bảng thông tin'!$B$4:$R$1002,11,0) -> 500000 | L14: =+VLOOKUP($B14,'Bảng thông tin'!$B$4:$R$1002,12,0) -> 400000 | M14: =+VLOOKUP($B14,'Bảng thông tin'!$B$4:$R$1002,13,0) -> 400000 | N14: =+VLOOKUP($B14,'Bảng thông tin'!$B$4:$R$1002,14,0) -> 10600000 | O14: =VLOOKUP($B14,BCC!$B$11:$AN$1032,35,0) -> 26 | P14: =VLOOKUP($B14,BCC!$B$11:$AN$1032,38,0)+VLOOKUP($B14,BCC!$B$11:$AN$1032,39,0) -> 0 | Q14: =+((H14+I14)/26)*P14 -> 0 | R14: =VLOOKUP($B14,BCC!$B$11:$AN$1032,36,0) -> 0 | S14: =ROUND(((H14+I14)/26)/8*R14*1.5,0) -> 0 | T14: =VLOOKUP($B14,BCC!$B$11:$AN$1032,37,0) -> 8 | U14: =ROUND(((H14+I14)/26)/8*T14*2,0) -> 615385 | V14: =IF($D14="HĐTV",(H14/26)*$O14*0.85,(H14/26)*$O14) -> 7000000 | W14: =IF($D14="HĐTV",(I14/26)*$O14*0.85,($I14/26)*$O14) -> 1000000 | X14: =(J14/26)*$O14 -> 1300000 | Y14: =(K14/26)*$O14 -> 500000 | Z14: =(L14/26)*$O14 -> 400000 | AA14: =IF($D14="HĐTV",M14/26*O14,(M14)) -> 400000 | AB14: =VLOOKUP($B14,'Bảng thông tin'!$B:$R,15,0)+VLOOKUP(B14,'Bảng thông tin'!$B:$Q,16,0) -> 0 | AC14: =+SUM(V14:AB14)+Q14+S14+U14 -> 11215385 | AD14: =X14 -> 1300000 | AE14: =IF($D14="HĐTV",0,Z14) -> 400000 | AF14: =IF($D14="HĐTV",0,IF(AA14<=(5000000/12),AA14,AA14-(AA14-(5000000/12)))) -> 400000 | AG14: =+S14+U14 -> 615385 | AH14: =+SUM(AD14:AG14) -> 2715385 | AI14: =IFERROR(IF($O14<14,0,$G14*17%),0) -> 1360000 | AJ14: =IFERROR(IF($O14<14,0,$G14*3%),0) -> 240000 | AK14: =IFERROR(IF($O14<14,0,$G14*1%),0) -> 80000 | AL14: =IFERROR(IF($O14<14,0,$G14*0.5%),0) -> 40000 | AM14: =IFERROR(SUM(AI14:AL14),0) -> 1720000 | AN14: =IFERROR($G14*2%,0) -> 160000 | AO14: =IFERROR(IF($O14<14,0,$G14*8%),0) -> 640000 | AP14: =IFERROR(IF($O14<14,0,$G14*1.5%),0) -> 120000 | AQ14: =IFERROR(IF($O14<14,0,$G14*1%),0) -> 80000 | AR14: =SUM(AO14:AQ14) -> 840000 | AS14: =+SUM($G$4)*0% -> 0 | AT14: =IF($D14="HĐTV",0,15500000) -> 15500000 | AV14: =+AU14*6200000 -> 0 | AW14: =+AT14+AV14 -> 15500000 | AX14: =ROUND(AC14-AH14,0) -> 8500000 | AY14: =IF(AX14-AW14-AR14-AS14<0,0,AX14-AW14-AR14-AS14) -> 0 | AZ14: =IF(D14="HĐLĐ",IF(AY14<=10000000,AY14*5%,IF(AY14<=30000000,AY14*10%-500000,IF(AY14<=60000000,AY14*20%-3500000,IF(AY14<=100000000,AY14*30%-9500000,AY14*35%-14500000)))),AY14*10%) -> 0 | BA14: =+VLOOKUP($B14,'Bảng thông tin'!$B:$R,16,0) -> 0 | BB14: =ROUND(AC14-AZ14-AR14-AS14-BA14,0) -> 10375385
A15: 12 | B15: NV020 | C15: =+VLOOKUP($B15,'Bảng thông tin'!$B$4:$R$1002,2,0) -> Dương Nhựt Thành | D15: =+VLOOKUP($B15,'Bảng thông tin'!$B$4:$R$1002,3,0) -> HĐLĐ | E15: Nhân viên | F15: Logistic | G15: =+VLOOKUP($B15,'Bảng thông tin'!$B$4:$R$1002,7,0) -> 7000000 | H15: =+VLOOKUP($B15,'Bảng thông tin'!$B$4:$R$1002,8,0) -> 6500000 | I15: =+VLOOKUP($B15,'Bảng thông tin'!$B$4:$R$1002,9,0) -> 500000 | J15: =+VLOOKUP($B15,'Bảng thông tin'!$B$4:$R$1002,10,0) -> 1000000 | K15: =+VLOOKUP($B15,'Bảng thông tin'!$B$4:$R$1002,11,0) -> 1000000 | L15: =+VLOOKUP($B15,'Bảng thông tin'!$B$4:$R$1002,12,0) -> 500000 | M15: =+VLOOKUP($B15,'Bảng thông tin'!$B$4:$R$1002,13,0) -> 400000 | N15: =+VLOOKUP($B15,'Bảng thông tin'!$B$4:$R$1002,14,0) -> 9900000 | O15: =VLOOKUP($B15,BCC!$B$11:$AN$1032,35,0) -> 24 | P15: =VLOOKUP($B15,BCC!$B$11:$AN$1032,38,0)+VLOOKUP($B15,BCC!$B$11:$AN$1032,39,0) -> 2 | Q15: =+((H15+I15)/26)*P15 -> 538461.54 | R15: =VLOOKUP($B15,BCC!$B$11:$AN$1032,36,0) -> 0 | S15: =ROUND(((H15+I15)/26)/8*R15*1.5,0) -> 0 | T15: =VLOOKUP($B15,BCC!$B$11:$AN$1032,37,0) -> 0 | U15: =ROUND(((H15+I15)/26)/8*T15*2,0) -> 0 | V15: =IF($D15="HĐTV",(H15/26)*$O15*0.85,(H15/26)*$O15) -> 6000000 | W15: =IF($D15="HĐTV",(I15/26)*$O15*0.85,($I15/26)*$O15) -> 461538.46 | X15: =(J15/26)*$O15 -> 923076.92 | Y15: =(K15/26)*$O15 -> 923076.92 | Z15: =(L15/26)*$O15 -> 461538.46 | AA15: =IF($D15="HĐTV",M15/26*O15,(M15)) -> 400000 | AB15: =VLOOKUP($B15,'Bảng thông tin'!$B:$R,15,0)+VLOOKUP(B15,'Bảng thông tin'!$B:$Q,16,0) -> 0 | AC15: =+SUM(V15:AB15)+Q15+S15+U15 -> 9707692.3 | AD15: =X15 -> 923076.92 | AE15: =IF($D15="HĐTV",0,Z15) -> 461538.46 | AF15: =IF($D15="HĐTV",0,IF(AA15<=(5000000/12),AA15,AA15-(AA15-(5000000/12)))) -> 400000 | AG15: =+S15+U15 -> 0 | AH15: =+SUM(AD15:AG15) -> 1784615.4 | AI15: =IFERROR(IF($O15<14,0,$G15*17%),0) -> 1190000 | AJ15: =IFERROR(IF($O15<14,0,$G15*3%),0) -> 210000 | AK15: =IFERROR(IF($O15<14,0,$G15*1%),0) -> 70000 | AL15: =IFERROR(IF($O15<14,0,$G15*0.5%),0) -> 35000 | AM15: =IFERROR(SUM(AI15:AL15),0) -> 1505000 | AN15: =IFERROR($G15*2%,0) -> 140000 | AO15: =IFERROR(IF($O15<14,0,$G15*8%),0) -> 560000 | AP15: =IFERROR(IF($O15<14,0,$G15*1.5%),0) -> 105000 | AQ15: =IFERROR(IF($O15<14,0,$G15*1%),0) -> 70000 | AR15: =SUM(AO15:AQ15) -> 735000 | AS15: =+SUM($G$4)*0% -> 0 | AT15: =IF($D15="HĐTV",0,15500000) -> 15500000 | AV15: =+AU15*6200000 -> 0 | AW15: =+AT15+AV15 -> 15500000 | AX15: =ROUND(AC15-AH15,0) -> 7923077 | AY15: =IF(AX15-AW15-AR15-AS15<0,0,AX15-AW15-AR15-AS15) -> 0 | AZ15: =IF(D15="HĐLĐ",IF(AY15<=10000000,AY15*5%,IF(AY15<=30000000,AY15*10%-500000,IF(AY15<=60000000,AY15*20%-3500000,IF(AY15<=100000000,AY15*30%-9500000,AY15*35%-14500000)))),AY15*10%) -> 0 | BA15: =+VLOOKUP($B15,'Bảng thông tin'!$B:$R,16,0) -> 0 | BB15: =ROUND(AC15-AZ15-AR15-AS15-BA15,0) -> 8972692
A16: 13 | B16: NV031 | C16: =+VLOOKUP($B16,'Bảng thông tin'!$B$4:$R$1002,2,0) -> Tiết Trinh Nguyên | D16: =+VLOOKUP($B16,'Bảng thông tin'!$B$4:$R$1002,3,0) -> HĐLĐ | E16: Nhân viên | F16: Logistic | G16: =+VLOOKUP($B16,'Bảng thông tin'!$B$4:$R$1002,7,0) -> 7000000 | H16: =+VLOOKUP($B16,'Bảng thông tin'!$B$4:$R$1002,8,0) -> 6500000 | I16: =+VLOOKUP($B16,'Bảng thông tin'!$B$4:$R$1002,9,0) -> 500000 | J16: =+VLOOKUP($B16,'Bảng thông tin'!$B$4:$R$1002,10,0) -> 1000000 | K16: =+VLOOKUP($B16,'Bảng thông tin'!$B$4:$R$1002,11,0) -> 500000 | L16: =+VLOOKUP($B16,'Bảng thông tin'!$B$4:$R$1002,12,0) -> 300000 | M16: =+VLOOKUP($B16,'Bảng thông tin'!$B$4:$R$1002,13,0) -> 400000 | N16: =+VLOOKUP($B16,'Bảng thông tin'!$B$4:$R$1002,14,0) -> 9200000 | O16: =VLOOKUP($B16,BCC!$B$11:$AN$1032,35,0) -> 25 | P16: =VLOOKUP($B16,BCC!$B$11:$AN$1032,38,0)+VLOOKUP($B16,BCC!$B$11:$AN$1032,39,0) -> 1 | Q16: =+((H16+I16)/26)*P16 -> 269230.77 | R16: =VLOOKUP($B16,BCC!$B$11:$AN$1032,36,0) -> 21.33 | S16: =ROUND(((H16+I16)/26)/8*R16*1.5,0) -> 1076755 | T16: =VLOOKUP($B16,BCC!$B$11:$AN$1032,37,0) -> 0 | U16: =ROUND(((H16+I16)/26)/8*T16*2,0) -> 0 | V16: =IF($D16="HĐTV",(H16/26)*$O16*0.85,(H16/26)*$O16) -> 6250000 | W16: =IF($D16="HĐTV",(I16/26)*$O16*0.85,($I16/26)*$O16) -> 480769.23 | X16: =(J16/26)*$O16 -> 961538.46 | Y16: =(K16/26)*$O16 -> 480769.23 | Z16: =(L16/26)*$O16 -> 288461.54 | AA16: =IF($D16="HĐTV",M16/26*O16,(M16)) -> 400000 | AB16: =VLOOKUP($B16,'Bảng thông tin'!$B:$R,15,0)+VLOOKUP(B16,'Bảng thông tin'!$B:$Q,16,0) -> 0 | AC16: =+SUM(V16:AB16)+Q16+S16+U16 -> 10207524 | AD16: =X16 -> 961538.46 | AE16: =IF($D16="HĐTV",0,Z16) -> 288461.54 | AF16: =IF($D16="HĐTV",0,IF(AA16<=(5000000/12),AA16,AA16-(AA16-(5000000/12)))) -> 400000 | AG16: =+S16+U16 -> 1076755 | AH16: =+SUM(AD16:AG16) -> 2726755 | AI16: =IFERROR(IF($O16<14,0,$G16*17%),0) -> 1190000 | AJ16: =IFERROR(IF($O16<14,0,$G16*3%),0) -> 210000 | AK16: =IFERROR(IF($O16<14,0,$G16*1%),0) -> 70000 | AL16: =IFERROR(IF($O16<14,0,$G16*0.5%),0) -> 35000 | AM16: =IFERROR(SUM(AI16:AL16),0) -> 1505000 | AN16: =IFERROR($G16*2%,0) -> 140000 | AO16: =IFERROR(IF($O16<14,0,$G16*8%),0) -> 560000 | AP16: =IFERROR(IF($O16<14,0,$G16*1.5%),0) -> 105000 | AQ16: =IFERROR(IF($O16<14,0,$G16*1%),0) -> 70000 | AR16: =SUM(AO16:AQ16) -> 735000 | AS16: =+SUM($G$4)*0% -> 0 | AT16: =IF($D16="HĐTV",0,15500000) -> 15500000 | AV16: =+AU16*6200000 -> 0 | AW16: =+AT16+AV16 -> 15500000 | AX16: =ROUND(AC16-AH16,0) -> 7480769 | AY16: =IF(AX16-AW16-AR16-AS16<0,0,AX16-AW16-AR16-AS16) -> 0 | AZ16: =IF(D16="HĐLĐ",IF(AY16<=10000000,AY16*5%,IF(AY16<=30000000,AY16*10%-500000,IF(AY16<=60000000,AY16*20%-3500000,IF(AY16<=100000000,AY16*30%-9500000,AY16*35%-14500000)))),AY16*10%) -> 0 | BA16: =+VLOOKUP($B16,'Bảng thông tin'!$B:$R,16,0) -> 0 | BB16: =ROUND(AC16-AZ16-AR16-AS16-BA16,0) -> 9472524
A17: 14 | B17: NV036 | C17: =+VLOOKUP($B17,'Bảng thông tin'!$B$4:$R$1002,2,0) -> Nguyễn Hoàng Ngọc Châu | D17: =+VLOOKUP($B17,'Bảng thông tin'!$B$4:$R$1002,3,0) -> HĐLĐ | E17: Nhân viên | F17: Logistic | G17: =+VLOOKUP($B17,'Bảng thông tin'!$B$4:$R$1002,7,0) -> 7500000 | H17: =+VLOOKUP($B17,'Bảng thông tin'!$B$4:$R$1002,8,0) -> 6500000 | I17: =+VLOOKUP($B17,'Bảng thông tin'!$B$4:$R$1002,9,0) -> 1000000 | J17: =+VLOOKUP($B17,'Bảng thông tin'!$B$4:$R$1002,10,0) -> 1000000 | K17: =+VLOOKUP($B17,'Bảng thông tin'!$B$4:$R$1002,11,0) -> 500000 | L17: =+VLOOKUP($B17,'Bảng thông tin'!$B$4:$R$1002,12,0) -> 400000 | M17: =+VLOOKUP($B17,'Bảng thông tin'!$B$4:$R$1002,13,0) -> 400000 | N17: =+VLOOKUP($B17,'Bảng thông tin'!$B$4:$R$1002,14,0) -> 9800000 | O17: =VLOOKUP($B17,BCC!$B$11:$AN$1032,35,0) -> 26 | P17: =VLOOKUP($B17,BCC!$B$11:$AN$1032,38,0)+VLOOKUP($B17,BCC!$B$11:$AN$1032,39,0) -> 0 | Q17: =+((H17+I17)/26)*P17 -> 0 | R17: =VLOOKUP($B17,BCC!$B$11:$AN$1032,36,0) -> 10.58 | S17: =ROUND(((H17+I17)/26)/8*R17*1.5,0) -> 572236 | T17: =VLOOKUP($B17,BCC!$B$11:$AN$1032,37,0) -> 0 | U17: =ROUND(((H17+I17)/26)/8*T17*2,0) -> 0 | V17: =IF($D17="HĐTV",(H17/26)*$O17*0.85,(H17/26)*$O17) -> 6500000 | W17: =IF($D17="HĐTV",(I17/26)*$O17*0.85,($I17/26)*$O17) -> 1000000 | X17: =(J17/26)*$O17 -> 1000000 | Y17: =(K17/26)*$O17 -> 500000 | Z17: =(L17/26)*$O17 -> 400000 | AA17: =IF($D17="HĐTV",M17/26*O17,(M17)) -> 400000 | AB17: =VLOOKUP($B17,'Bảng thông tin'!$B:$R,15,0)+VLOOKUP(B17,'Bảng thông tin'!$B:$Q,16,0) -> 0 | AC17: =+SUM(V17:AB17)+Q17+S17+U17 -> 10372236 | AD17: =X17 -> 1000000 | AE17: =IF($D17="HĐTV",0,Z17) -> 400000 | AF17: =IF($D17="HĐTV",0,IF(AA17<=(5000000/12),AA17,AA17-(AA17-(5000000/12)))) -> 400000 | AG17: =+S17+U17 -> 572236 | AH17: =+SUM(AD17:AG17) -> 2372236 | AI17: =IFERROR(IF($O17<14,0,$G17*17%),0) -> 1275000 | AJ17: =IFERROR(IF($O17<14,0,$G17*3%),0) -> 225000 | AK17: =IFERROR(IF($O17<14,0,$G17*1%),0) -> 75000 | AL17: =IFERROR(IF($O17<14,0,$G17*0.5%),0) -> 37500 | AM17: =IFERROR(SUM(AI17:AL17),0) -> 1612500 | AN17: =IFERROR($G17*2%,0) -> 150000 | AO17: =IFERROR(IF($O17<14,0,$G17*8%),0) -> 600000 | AP17: =IFERROR(IF($O17<14,0,$G17*1.5%),0) -> 112500 | AQ17: =IFERROR(IF($O17<14,0,$G17*1%),0) -> 75000 | AR17: =SUM(AO17:AQ17) -> 787500 | AS17: =+SUM($G$4)*0% -> 0 | AT17: =IF($D17="HĐTV",0,15500000) -> 15500000 | AV17: =+AU17*6200000 -> 0 | AW17: =+AT17+AV17 -> 15500000 | AX17: =ROUND(AC17-AH17,0) -> 8000000 | AY17: =IF(AX17-AW17-AR17-AS17<0,0,AX17-AW17-AR17-AS17) -> 0 | AZ17: =IF(D17="HĐLĐ",IF(AY17<=10000000,AY17*5%,IF(AY17<=30000000,AY17*10%-500000,IF(AY17<=60000000,AY17*20%-3500000,IF(AY17<=100000000,AY17*30%-9500000,AY17*35%-14500000)))),AY17*10%) -> 0 | BA17: =+VLOOKUP($B17,'Bảng thông tin'!$B:$R,16,0) -> 0 | BB17: =ROUND(AC17-AZ17-AR17-AS17-BA17,0) -> 9584736
... A35: 32 | B35: NV009 | C35: =+VLOOKUP($B35,'Bảng thông tin'!$B$4:$R$1002,2,0) -> Trần Thị Thanh Dung | D35: =+VLOOKUP($B35,'Bảng thông tin'!$B$4:$R$1002,3,0) -> HĐLĐ | E35: Kế toán | F35: Kế toán | G35: =+VLOOKUP($B35,'Bảng thông tin'!$B$4:$R$1002,7,0) -> 8500000 | H35: =+VLOOKUP($B35,'Bảng thông tin'!$B$4:$R$1002,8,0) -> 7500000 | I35: =+VLOOKUP($B35,'Bảng thông tin'!$B$4:$R$1002,9,0) -> 1000000 | J35: =+VLOOKUP($B35,'Bảng thông tin'!$B$4:$R$1002,10,0) -> 1800000 | K35: =+VLOOKUP($B35,'Bảng thông tin'!$B$4:$R$1002,11,0) -> 500000 | L35: =+VLOOKUP($B35,'Bảng thông tin'!$B$4:$R$1002,12,0) -> 300000 | M35: =+VLOOKUP($B35,'Bảng thông tin'!$B$4:$R$1002,13,0) -> 400000 | N35: =+VLOOKUP($B35,'Bảng thông tin'!$B$4:$R$1002,14,0) -> 11500000 | O35: =VLOOKUP($B35,BCC!$B$11:$AN$1032,35,0) -> 17 | P35: =VLOOKUP($B35,BCC!$B$11:$AN$1032,38,0)+VLOOKUP($B35,BCC!$B$11:$AN$1032,39,0) -> 0 | Q35: =+((H35+I35)/26)*P35 -> 0 | R35: =VLOOKUP($B35,BCC!$B$11:$AN$1032,36,0) -> 0 | S35: =ROUND(((H35+I35)/26)/8*R35*1.5,0) -> 0 | T35: =VLOOKUP($B35,BCC!$B$11:$AN$1032,37,0) -> 0 | U35: =ROUND(((H35+I35)/26)/8*T35*2,0) -> 0 | V35: =IF($D35="HĐTV",(H35/26)*$O35*0.85,(H35/26)*$O35) -> 4903846.2 | W35: =IF($D35="HĐTV",(I35/26)*$O35*0.85,($I35/26)*$O35) -> 653846.15 | X35: =(J35/26)*$O35 -> 1176923.1 | Y35: =(K35/26)*$O35 -> 326923.08 | Z35: =(L35/26)*$O35 -> 196153.85 | AA35: =IF($D35="HĐTV",M35/26*O35,(M35)) -> 400000 | AB35: =VLOOKUP($B35,'Bảng thông tin'!$B:$R,15,0)+VLOOKUP(B35,'Bảng thông tin'!$B:$Q,16,0) -> 0 | AC35: =+SUM(V35:AB35)+Q35+S35+U35 -> 7657692.3 | AD35: =X35 -> 1176923.1 | AE35: =IF($D35="HĐTV",0,Z35) -> 196153.85 | AF35: =IF($D35="HĐTV",0,IF(AA35<=(5000000/12),AA35,AA35-(AA35-(5000000/12)))) -> 400000 | AG35: =+S35+U35 -> 0 | AH35: =+SUM(AD35:AG35) -> 1773076.9 | AI35: =IFERROR(IF($O35<14,0,$G35*17%),0) -> 1445000 | AJ35: =IFERROR(IF($O35<14,0,$G35*3%),0) -> 255000 | AK35: =IFERROR(IF($O35<14,0,$G35*1%),0) -> 85000 | AL35: =IFERROR(IF($O35<14,0,$G35*0.5%),0) -> 42500 | AM35: =IFERROR(SUM(AI35:AL35),0) -> 1827500 | AN35: =IFERROR($G35*2%,0) -> 170000 | AO35: =IFERROR(IF($O35<14,0,$G35*8%),0) -> 680000 | AP35: =IFERROR(IF($O35<14,0,$G35*1.5%),0) -> 127500 | AQ35: =IFERROR(IF($O35<14,0,$G35*1%),0) -> 85000 | AR35: =SUM(AO35:AQ35) -> 892500 | AS35: =+SUM($G$4)*0% -> 0 | AT35: =IF($D35="HĐTV",0,15500000) -> 15500000 | AV35: =+AU35*6200000 -> 0 | AW35: =+AT35+AV35 -> 15500000 | AX35: =ROUND(AC35-AH35,0) -> 5884615 | AY35: =IF(AX35-AW35-AR35-AS35<0,0,AX35-AW35-AR35-AS35) -> 0 | AZ35: =IF(D35="HĐLĐ",IF(AY35<=10000000,AY35*5%,IF(AY35<=30000000,AY35*10%-500000,IF(AY35<=60000000,AY35*20%-3500000,IF(AY35<=100000000,AY35*30%-9500000,AY35*35%-14500000)))),AY35*10%) -> 0 | BA35: =+VLOOKUP($B35,'Bảng thông tin'!$B:$R,16,0) -> 0 | BB35: =ROUND(AC35-AZ35-AR35-AS35-BA35,0) -> 6765192
A36: 33 | B36: NV037 | C36: =+VLOOKUP($B36,'Bảng thông tin'!$B$4:$R$1002,2,0) -> Vũ Thị Mai Thủy | D36: =+VLOOKUP($B36,'Bảng thông tin'!$B$4:$R$1002,3,0) -> HĐLĐ | E36: Kế toán trưởng | F36: Kế toán | G36: =+VLOOKUP($B36,'Bảng thông tin'!$B$4:$R$1002,7,0) -> 10000000 | H36: =+VLOOKUP($B36,'Bảng thông tin'!$B$4:$R$1002,8,0) -> 8500000 | I36: =+VLOOKUP($B36,'Bảng thông tin'!$B$4:$R$1002,9,0) -> 1500000 | J36: =+VLOOKUP($B36,'Bảng thông tin'!$B$4:$R$1002,10,0) -> 1800000 | K36: =+VLOOKUP($B36,'Bảng thông tin'!$B$4:$R$1002,11,0) -> 500000 | L36: =+VLOOKUP($B36,'Bảng thông tin'!$B$4:$R$1002,12,0) -> 500000 | M36: =+VLOOKUP($B36,'Bảng thông tin'!$B$4:$R$1002,13,0) -> 400000 | N36: =+VLOOKUP($B36,'Bảng thông tin'!$B$4:$R$1002,14,0) -> 13200000 | O36: =VLOOKUP($B36,BCC!$B$11:$AN$1032,35,0) -> 25 | P36: =VLOOKUP($B36,BCC!$B$11:$AN$1032,38,0)+VLOOKUP($B36,BCC!$B$11:$AN$1032,39,0) -> 1 | Q36: =+((H36+I36)/26)*P36 -> 384615.38 | R36: =VLOOKUP($B36,BCC!$B$11:$AN$1032,36,0) -> 6.32 | S36: =ROUND(((H36+I36)/26)/8*R36*1.5,0) -> 455769 | T36: =VLOOKUP($B36,BCC!$B$11:$AN$1032,37,0) -> 0 | U36: =ROUND(((H36+I36)/26)/8*T36*2,0) -> 0 | V36: =IF($D36="HĐTV",(H36/26)*$O36*0.85,(H36/26)*$O36) -> 8173076.9 | W36: =IF($D36="HĐTV",(I36/26)*$O36*0.85,($I36/26)*$O36) -> 1442307.7 | X36: =(J36/26)*$O36 -> 1730769.2 | Y36: =(K36/26)*$O36 -> 480769.23 | Z36: =(L36/26)*$O36 -> 480769.23 | AA36: =IF($D36="HĐTV",0,(M36)) -> 400000 | AB36: =VLOOKUP($B36,'Bảng thông tin'!$B:$R,15,0)+VLOOKUP(B36,'Bảng thông tin'!$B:$Q,16,0) -> 0 | AC36: =+SUM(V36:AB36)+Q36+S36+U36 -> 13548077 | AD36: =X36 -> 1730769.2 | AE36: =IF($D36="HĐTV",0,Z36) -> 480769.23 | AF36: =IF($D36="HĐTV",0,IF(AA36<=(5000000/12),AA36,AA36-(AA36-(5000000/12)))) -> 400000 | AG36: =+S36+U36 -> 455769 | AH36: =+SUM(AD36:AG36) -> 3067307.5 | AI36: =IFERROR(IF($O36<14,0,$G36*17%),0) -> 1700000 | AJ36: =IFERROR(IF($O36<14,0,$G36*3%),0) -> 300000 | AK36: =IFERROR(IF($O36<14,0,$G36*1%),0) -> 100000 | AL36: =IFERROR(IF($O36<14,0,$G36*0.5%),0) -> 50000 | AM36: =IFERROR(SUM(AI36:AL36),0) -> 2150000 | AN36: =IFERROR($G36*2%,0) -> 200000 | AO36: =IFERROR(IF($O36<14,0,$G36*8%),0) -> 800000 | AP36: =IFERROR(IF($O36<14,0,$G36*1.5%),0) -> 150000 | AQ36: =IFERROR(IF($O36<14,0,$G36*1%),0) -> 100000 | AR36: =SUM(AO36:AQ36) -> 1050000 | AS36: =+SUM($G$4)*0% -> 0 | AT36: =IF($D36="HĐTV",0,15500000) -> 15500000 | AV36: =+AU36*6200000 -> 0 | AW36: =+AT36+AV36 -> 15500000 | AX36: =ROUND(AC36-AH36,0) -> 10480769 | AY36: =IF(AX36-AW36-AR36-AS36<0,0,AX36-AW36-AR36-AS36) -> 0 | AZ36: =IF(D36="HĐLĐ",IF(AY36<=10000000,AY36*5%,IF(AY36<=30000000,AY36*10%-500000,IF(AY36<=60000000,AY36*20%-3500000,IF(AY36<=100000000,AY36*30%-9500000,AY36*35%-14500000)))),AY36*10%) -> 0 | BA36: =+VLOOKUP($B36,'Bảng thông tin'!$B:$R,16,0) -> 0 | BB36: =ROUND(AC36-AZ36-AR36-AS36-BA36,0) -> 12498077
A37: 34 | B37: NV038 | C37: =+VLOOKUP($B37,'Bảng thông tin'!$B$4:$R$1002,2,0) -> Phạm Thị Kim Trang | D37: =+VLOOKUP($B37,'Bảng thông tin'!$B$4:$R$1002,3,0) -> HĐLĐ | E37: Nhân viên | F37: Kinh doanh | G37: =+VLOOKUP($B37,'Bảng thông tin'!$B$4:$R$1002,7,0) -> 7000000 | H37: =+VLOOKUP($B37,'Bảng thông tin'!$B$4:$R$1002,8,0) -> 6500000 | I37: =+VLOOKUP($B37,'Bảng thông tin'!$B$4:$R$1002,9,0) -> 500000 | J37: =+VLOOKUP($B37,'Bảng thông tin'!$B$4:$R$1002,10,0) -> 1000000 | K37: =+VLOOKUP($B37,'Bảng thông tin'!$B$4:$R$1002,11,0) -> 500000 | L37: =+VLOOKUP($B37,'Bảng thông tin'!$B$4:$R$1002,12,0) -> 400000 | M37: =+VLOOKUP($B37,'Bảng thông tin'!$B$4:$R$1002,13,0) -> 400000 | N37: =+VLOOKUP($B37,'Bảng thông tin'!$B$4:$R$1002,14,0) -> 9300000 | O37: =VLOOKUP($B37,BCC!$B$11:$AN$1032,35,0) -> 26 | P37: =VLOOKUP($B37,BCC!$B$11:$AN$1032,38,0)+VLOOKUP($B37,BCC!$B$11:$AN$1032,39,0) -> 0 | Q37: =+((H37+I37)/26)*P37 -> 0 | R37: =VLOOKUP($B37,BCC!$B$11:$AN$1032,36,0) -> 8.8 | S37: =ROUND(((H37+I37)/26)/8*R37*1.5,0) -> 444231 | T37: =VLOOKUP($B37,BCC!$B$11:$AN$1032,37,0) -> 8 | U37: =ROUND(((H37+I37)/26)/8*T37*2,0) -> 538462 | V37: =IF($D37="HĐTV",(H37/26)*$O37*0.85,(H37/26)*$O37) -> 6500000 | W37: =IF($D37="HĐTV",(I37/26)*$O37*0.85,($I37/26)*$O37) -> 500000 | X37: =(J37/26)*$O37 -> 1000000 | Y37: =(K37/26)*$O37 -> 500000 | Z37: =(L37/26)*$O37 -> 400000 | AA37: =IF($D37="HĐTV",0,(M37)) -> 400000 | AB37: =VLOOKUP($B37,'Bảng thông tin'!$B:$R,15,0)+VLOOKUP(B37,'Bảng thông tin'!$B:$Q,16,0) -> 0 | AC37: =+SUM(V37:AB37)+Q37+S37+U37 -> 10282693 | AD37: =X37 -> 1000000 | AE37: =IF($D37="HĐTV",0,Z37) -> 400000 | AF37: =IF($D37="HĐTV",0,IF(AA37<=(5000000/12),AA37,AA37-(AA37-(5000000/12)))) -> 400000 | AG37: =+S37+U37 -> 982693 | AH37: =+SUM(AD37:AG37) -> 2782693 | AI37: =IFERROR(IF($O37<14,0,$G37*17%),0) -> 1190000 | AJ37: =IFERROR(IF($O37<14,0,$G37*3%),0) -> 210000 | AK37: =IFERROR(IF($O37<14,0,$G37*1%),0) -> 70000 | AL37: =IFERROR(IF($O37<14,0,$G37*0.5%),0) -> 35000 | AM37: =IFERROR(SUM(AI37:AL37),0) -> 1505000 | AN37: =IFERROR($G37*2%,0) -> 140000 | AO37: =IFERROR(IF($O37<14,0,$G37*8%),0) -> 560000 | AP37: =IFERROR(IF($O37<14,0,$G37*1.5%),0) -> 105000 | AQ37: =IFERROR(IF($O37<14,0,$G37*1%),0) -> 70000 | AR37: =SUM(AO37:AQ37) -> 735000 | AS37: =+SUM($G$4)*0% -> 0 | AT37: =IF($D37="HĐTV",0,15500000) -> 15500000 | AV37: =+AU37*6200000 -> 0 | AW37: =+AT37+AV37 -> 15500000 | AX37: =ROUND(AC37-AH37,0) -> 7500000 | AY37: =IF(AX37-AW37-AR37-AS37<0,0,AX37-AW37-AR37-AS37) -> 0 | AZ37: =IF(D37="HĐLĐ",IF(AY37<=10000000,AY37*5%,IF(AY37<=30000000,AY37*10%-500000,IF(AY37<=60000000,AY37*20%-3500000,IF(AY37<=100000000,AY37*30%-9500000,AY37*35%-14500000)))),AY37*10%) -> 0 | BA37: =+VLOOKUP($B37,'Bảng thông tin'!$B:$R,16,0) -> 0 | BB37: =ROUND(AC37-AZ37-AR37-AS37-BA37,0) -> 9547693
